Workbook

Sheet Сводка
A1: Флип-модель: Kernweg 1, Хорн — сводка
A2: Купить пустым за свои средства → сдать → продать сданным инвестору. Все цифры — формулы от листов «Допущения» и «Аренда».
A4: Покупка
A5: Цена покупки | B5: =buy_price -> 1150000
A6: Налог на передачу 10,4 % | B6: =buy_price*ovb -> 119600
A7: Нотариус и кадастр | B7: =notary -> 3500
A8: Проверка объекта | B8: =dd -> 7500
A9: Оценка для банка | B9: =IF(ltv>0,valuation,0) -> 0
A10: Консультант по покупке | B10: =buy_price*advisory -> 11500
A11: Комиссия банка | B11: =loan*bank_fee -> 0
A12: Итого на покупку | B12: =SUM(B5:B11) -> 1292100
A13: Кредит | B13: =buy_price*ltv -> 0
A14: Ремонт с НДС | B14: =(capex_m2*area_vvo+capex_fixed)*(1+capex_vat) -> 51812.2
A15: Продажа
A16: Аренда в год (сценарий) | B16: =rent_eff -> 125625
A17: Первый оплачиваемый месяц | B17: =lease_month+rent_free -> 8
A18: Стоимость сданного здания: аренда / доходность для инвестора | B18: =rent_eff/exit_bar -> 1522727.3
A19: Минус не закончившиеся каникулы | B19: =MAX(0,first_paid-1-sale_month)*rent_eff/12 -> 0
A20: Плюс доля экономии покупателя по ст. 13 (продажа до 6 мес.) | B20: =IF(sale_month<=6,art13_share*ovb*buy_price/(1+ovb),0) -> 0 | C20: ст. 13 WBR: покупатель платит 10,4 % только с прироста цены
A21: Цена продажи | B21: =value_let-free_left+uplift -> 1522727.3 | C21: продажа сданного объекта инвестору; расходы на сделку платит покупатель (k.k.)
A22: Расходы на продажу | B22: =sale_price*sale_fee+sale_fixed -> 21534.091
A23: Результат
A24: Доходы: аренда за период и продажа | B24: =SUM('Денежный поток'!B10:Z10)+SUM('Денежный поток'!B13:Z13) -> 1575071
A25: Все затраты: цена, налоги, ремонт, комиссии | B25: =-(SUM('Денежный поток'!B5:Z9)+SUM('Денежный поток'!B11:Z11)+SUM('Денежный поток'!B14:Z14)) -> 1394706
A26: Прибыль до налога | B26: =SUM('Денежный поток'!B15:Z15) -> 180364.98
A27: Заработок на каждые € 100 затрат | B27: =profit/cost_total*100 -> 12.932114 | C27: прибыль до налога, делённая на все затраты
A28: Налог на прибыль VPB | B28: =IF(profit<=0,0,MIN(profit,vpb_step)*vpb_low+MAX(0,profit-vpb_step)*vpb_high) -> 34269.347
A29: Прибыль после налога | B29: =profit-vpb -> 146095.64
A30: Вложено своих денег на пике | B30: =-MIN('Денежный поток'!B16:Z16) -> 1370296.9 | C30: сколько денег занято в проекте в самый затратный момент; покупка без кредита
A31: Прибыль на свои деньги до налога | B31: =profit/equity -> 0.13162474
A32: Прибыль на свои деньги после налога | B32: =(profit-vpb)/equity -> 0.10661604
A33: Доходность своих денег в пересчёте на год (IRR), до налога | B33: =(1+IRR('Денежный поток'!B15:Z15,0.01))^12-1 -> 0.13410192 | C33: учитывает, сколько месяцев деньги заняты в проекте
A34: Доходность своих денег в пересчёте на год (IRR), после налога | B34: =(1+IRR('Денежный поток'!B18:Z18,0.01))^12-1 -> 0.10861727
A35: Сколько вернётся на € 1 своих денег, после налога | B35: =(equity+profit-vpb)/equity -> 1.106616 | C35: вложенное плюс чистая прибыль, делённые на вложенное
A36: Глазами покупателя
A37: Налог на передачу, который платит покупатель | B37: =IF(sale_month<=6,ovb*(sale_price-buy_price),ovb*sale_price) -> 158363.64
A38: Его полная цена | B38: =sale_price+buyer_ovb -> 1681090.9
A39: Его доходность на все расходы | B39: =rent_eff/buyer_total -> 0.074728261 | C39: сравнить с 8,5–8,9 % у сданных объектов в Хорне
A41: Потолок цены покупки (подбор моделью, базовые допущения)
A42: Прибыль 0 — дороже не покупать, продажа через 12 мес. | B42: 1311040 | C42: =B42/ask-1 -> -0.12305017
...

Sheet Допущения
A1: Флип-модель: Kernweg 1, Хорн — допущения
A2: Синие значения на жёлтом фоне можно менять: все листы пересчитаются. Суммы без НДС, евро.
A4: Покупка
A5: Цена продавца (k.k.) | B5: 1495000 | C5: funda in business, 16.10.2026
A6: Цена покупки — наше предложение | B6: 1150000 | C6: −23 % к цене продавца; потолок без убытка — см. «Сводка»
A7: Площадь, м² VVO (полезная) | B7: 2016 | C7: по объявлению: 2.016 м² VVO, 2.155 м² BVO
A8: Налог на передачу недвижимости | B8: 0.104 | C8: ст. 14 WBR, нежилая недвижимость, 2026–2027
A9: Нотариус и кадастр | B9: 3500 | C9: оценка
A10: Проверка объекта: техника, грунт, право | B10: 7500 | C10: оценка
A11: Оценка для банка | B11: 3500 | C11: оценка
A12: Консультант по покупке, % цены | B12: 0.01 | C12: оценка
A13: Подготовка к сдаче
A14: Ремонт, € на м² | B14: 20 | C14: покраска, свет, мелкий ремонт, разделение на два входа
A15: Ремонт, резерв | B15: 2500
A16: НДС на ремонт (расход, пока аренда без НДС) | B16: 0.21 | C16: при аренде с НДС возвращается
A17: Месяцев на ремонт | B17: 2
A18: Сдача в аренду
A19: Комиссия брокера, % годовой аренды | B19: 0.15 | C19: рынок 10–16 %
A20: Реклама и показы | B20: 1500
A21: Содержание
A22: Налог OZB, страховка, ремонт: % цены в год | B22: 0.006
A23: Энергия и охрана в простое, € на м² в год | B23: 3
A24: Кредит — по умолчанию не используется: покупка за свои средства
A25: Кредит, доля цены покупки (LTV) | B25: 0 | C25: 0 % — покупка за свои средства; можно поставить 50–60 %, чтобы сравнить
A26: Euribor 3M | B26: 0.02628 | C26: только если включить кредит; euribor-rates.eu, 14.10.2026
A27: Маржа банка | B27: 0.0275 | C27: только если включить кредит
A28: Комиссия банка, % кредита | B28: 0.01 | C28: только если включить кредит
A29: Продажа
A30: Брокер на продаже, % цены | B30: 0.0125
A31: Юрист и реклама продажи | B31: 2500
A32: Доля экономии покупателя по ст. 13 WBR, которую забираем в цене | B32: 0.5 | C32: только при продаже до 6 месяцев после нашей покупки
A33: Налог на прибыль (VPB) 2026
A34: Ставка до порога | B34: 0.19 | C34: KVK, 2026
A35: Ставка выше порога | B35: 0.258
A36: Порог | B36: 200000
A37: Ставка кредита | B37: =euribor+bank_margin -> 0.05378
A39: Сценарии
A40: Параметр | B40: Активный | D40: Пессимистичный | E40: Базовый | F40: Оптимистичный | G40: Ускоренный, 6 мес.
A41: Аренда, множитель к оценке | B41: =INDEX(D41:G41,scenario) -> 1 | D41: 0.9 | E41: 1 | F41: 1.1 | G41: 1
A42: Доходность выхода (BAR k.k.) | B42: =INDEX(D42:G42,scenario) -> 0.0825 | D42: 0.09 | E42: 0.0825 | F42: 0.0775 | G42: 0.0825
...

Sheet Денежный поток
A1: Денежный поток по месяцам
A2: Месяц 0 — передача у нотариуса и оплата; продажа — в конце месяца продажи
A3: Месяц | B3: 0 | C3: 1 | D3: 2 | E3: 3 | F3: 4 | G3: 5 | H3: 6 | I3: 7 | J3: 8 | K3: 9 | L3: 10 | M3: 11 | N3: 12 | O3: 13 | P3: 14 | Q3: 15 | R3: 16 | S3: 17 | T3: 18 | U3: 19 | V3: 20 | W3: 21 | X3: 22 | Y3: 23 | Z3: 24
A4: В работе (до продажи) | B4: =IF(B$3<=sale_month,1,0) -> 1 | C4: =IF(C$3<=sale_month,1,0) -> 1 | D4: =IF(D$3<=sale_month,1,0) -> 1 | E4: =IF(E$3<=sale_month,1,0) -> 1 | F4: =IF(F$3<=sale_month,1,0) -> 1 | G4: =IF(G$3<=sale_month,1,0) -> 1 | H4: =IF(H$3<=sale_month,1,0) -> 1 | I4: =IF(I$3<=sale_month,1,0) -> 1 | ... Z4: =IF(Z$3<=sale_month,1,0) -> 0
A5: Покупка и расходы на сделку | B5: =IF(B$3=0,-acq_total,0) -> -1292100 | C5: =IF(C$3=0,-acq_total,0) -> 0 | D5: =IF(D$3=0,-acq_total,0) -> 0 | E5: =IF(E$3=0,-acq_total,0) -> 0 | F5: =IF(F$3=0,-acq_total,0) -> 0 | G5: =IF(G$3=0,-acq_total,0) -> 0 | H5: =IF(H$3=0,-acq_total,0) -> 0 | I5: =IF(I$3=0,-acq_total,0) -> 0 | ... Z5: =IF(Z$3=0,-acq_total,0) -> 0
A6: Ремонт | B6: =IF(AND(B$3>=1,B$3<=capex_months,B$3<=sale_month),-capex_total/capex_months,0) -> 0 | C6: =IF(AND(C$3>=1,C$3<=capex_months,C$3<=sale_month),-capex_total/capex_months,0) -> -25906.1 | D6: =IF(AND(D$3>=1,D$3<=capex_months,D$3<=sale_month),-capex_total/capex_months,0) -> -25906.1 | E6: =IF(AND(E$3>=1,E$3<=capex_months,E$3<=sale_month),-capex_total/capex_months,0) -> 0 | F6: =IF(AND(F$3>=1,F$3<=capex_months,F$3<=sale_month),-capex_total/capex_months,0) -> 0 | G6: =IF(AND(G$3>=1,G$3<=capex_months,G$3<=sale_month),-capex_total/capex_months,0) -> 0 | H6: =IF(AND(H$3>=1,H$3<=capex_months,H$3<=sale_month),-capex_total/capex_months,0) -> 0 | I6: =IF(AND(I$3>=1,I$3<=capex_months,I$3<=sale_month),-capex_total/capex_months,0) -> 0 | ... Z6: =IF(AND(Z$3>=1,Z$3<=capex_months,Z$3<=sale_month),-capex_total/capex_months,0) -> 0
A7: Содержание | B7: =IF(AND(B$3>=1,B$3<=sale_month),-buy_price*holding_pct/12,0) -> 0 | C7: =IF(AND(C$3>=1,C$3<=sale_month),-buy_price*holding_pct/12,0) -> -575 | D7: =IF(AND(D$3>=1,D$3<=sale_month),-buy_price*holding_pct/12,0) -> -575 | E7: =IF(AND(E$3>=1,E$3<=sale_month),-buy_price*holding_pct/12,0) -> -575 | F7: =IF(AND(F$3>=1,F$3<=sale_month),-buy_price*holding_pct/12,0) -> -575 | G7: =IF(AND(G$3>=1,G$3<=sale_month),-buy_price*holding_pct/12,0) -> -575 | H7: =IF(AND(H$3>=1,H$3<=sale_month),-buy_price*holding_pct/12,0) -> -575 | I7: =IF(AND(I$3>=1,I$3<=sale_month),-buy_price*holding_pct/12,0) -> -575 | ... Z7: =IF(AND(Z$3>=1,Z$3<=sale_month),-buy_price*holding_pct/12,0) -> 0
A8: Энергия и охрана в простое | B8: =IF(AND(B$3>=1,B$3<lease_month,B$3<=sale_month),-void_m2*area_vvo/12,0) -> 0 | C8: =IF(AND(C$3>=1,C$3<lease_month,C$3<=sale_month),-void_m2*area_vvo/12,0) -> -504 | D8: =IF(AND(D$3>=1,D$3<lease_month,D$3<=sale_month),-void_m2*area_vvo/12,0) -> -504 | E8: =IF(AND(E$3>=1,E$3<lease_month,E$3<=sale_month),-void_m2*area_vvo/12,0) -> -504 | F8: =IF(AND(F$3>=1,F$3<lease_month,F$3<=sale_month),-void_m2*area_vvo/12,0) -> -504 | G8: =IF(AND(G$3>=1,G$3<lease_month,G$3<=sale_month),-void_m2*area_vvo/12,0) -> 0 | H8: =IF(AND(H$3>=1,H$3<lease_month,H$3<=sale_month),-void_m2*area_vvo/12,0) -> 0 | I8: =IF(AND(I$3>=1,I$3<lease_month,I$3<=sale_month),-void_m2*area_vvo/12,0) -> 0 | ... Z8: =IF(AND(Z$3>=1,Z$3<lease_month,Z$3<=sale_month),-void_m2*area_vvo/12,0) -> 0
A9: Сдача: брокер и реклама | B9: =IF(AND(B$3=lease_month,B$3<=sale_month),-(rent_eff*letting_fee+marketing),0) -> 0 | C9: =IF(AND(C$3=lease_month,C$3<=sale_month),-(rent_eff*letting_fee+marketing),0) -> 0 | D9: =IF(AND(D$3=lease_month,D$3<=sale_month),-(rent_eff*letting_fee+marketing),0) -> 0 | E9: =IF(AND(E$3=lease_month,E$3<=sale_month),-(rent_eff*letting_fee+marketing),0) -> 0 | F9: =IF(AND(F$3=lease_month,F$3<=sale_month),-(rent_eff*letting_fee+marketing),0) -> 0 | G9: =IF(AND(G$3=lease_month,G$3<=sale_month),-(rent_eff*letting_fee+marketing),0) -> -20343.75 | H9: =IF(AND(H$3=lease_month,H$3<=sale_month),-(rent_eff*letting_fee+marketing),0) -> 0 | I9: =IF(AND(I$3=lease_month,I$3<=sale_month),-(rent_eff*letting_fee+marketing),0) -> 0 | ... Z9: =IF(AND(Z$3=lease_month,Z$3<=sale_month),-(rent_eff*letting_fee+marketing),0) -> 0
A10: Аренда | B10: =IF(AND(B$3>=1,B$3>=first_paid,B$3<=sale_month),rent_eff/12,0) -> 0 | C10: =IF(AND(C$3>=1,C$3>=first_paid,C$3<=sale_month),rent_eff/12,0) -> 0 | D10: =IF(AND(D$3>=1,D$3>=first_paid,D$3<=sale_month),rent_eff/12,0) -> 0 | E10: =IF(AND(E$3>=1,E$3>=first_paid,E$3<=sale_month),rent_eff/12,0) -> 0 | F10: =IF(AND(F$3>=1,F$3>=first_paid,F$3<=sale_month),rent_eff/12,0) -> 0 | G10: =IF(AND(G$3>=1,G$3>=first_paid,G$3<=sale_month),rent_eff/12,0) -> 0 | H10: =IF(AND(H$3>=1,H$3>=first_paid,H$3<=sale_month),rent_eff/12,0) -> 0 | I10: =IF(AND(I$3>=1,I$3>=first_paid,I$3<=sale_month),rent_eff/12,0) -> 0 | ... Z10: =IF(AND(Z$3>=1,Z$3>=first_paid,Z$3<=sale_month),rent_eff/12,0) -> 0
A11: Проценты | B11: =IF(AND(B$3>=1,B$3<=sale_month),-loan*loan_rate/12,0) -> 0 | C11: =IF(AND(C$3>=1,C$3<=sale_month),-loan*loan_rate/12,0) -> 0 | D11: =IF(AND(D$3>=1,D$3<=sale_month),-loan*loan_rate/12,0) -> 0 | E11: =IF(AND(E$3>=1,E$3<=sale_month),-loan*loan_rate/12,0) -> 0 | F11: =IF(AND(F$3>=1,F$3<=sale_month),-loan*loan_rate/12,0) -> 0 | G11: =IF(AND(G$3>=1,G$3<=sale_month),-loan*loan_rate/12,0) -> 0 | H11: =IF(AND(H$3>=1,H$3<=sale_month),-loan*loan_rate/12,0) -> 0 | I11: =IF(AND(I$3>=1,I$3<=sale_month),-loan*loan_rate/12,0) -> 0 | ... Z11: =IF(AND(Z$3>=1,Z$3<=sale_month),-loan*loan_rate/12,0) -> 0
A12: Кредит: получен / погашен | B12: =IF(B$3=0,loan,0)-IF(B$3=sale_month,loan,0) -> 0 | C12: =IF(C$3=0,loan,0)-IF(C$3=sale_month,loan,0) -> 0 | D12: =IF(D$3=0,loan,0)-IF(D$3=sale_month,loan,0) -> 0 | E12: =IF(E$3=0,loan,0)-IF(E$3=sale_month,loan,0) -> 0 | F12: =IF(F$3=0,loan,0)-IF(F$3=sale_month,loan,0) -> 0 | G12: =IF(G$3=0,loan,0)-IF(G$3=sale_month,loan,0) -> 0 | H12: =IF(H$3=0,loan,0)-IF(H$3=sale_month,loan,0) -> 0 | I12: =IF(I$3=0,loan,0)-IF(I$3=sale_month,loan,0) -> 0 | ... Z12: =IF(Z$3=0,loan,0)-IF(Z$3=sale_month,loan,0) -> 0
A13: Продажа | B13: =IF(B$3=sale_month,sale_price,0) -> 0 | C13: =IF(C$3=sale_month,sale_price,0) -> 0 | D13: =IF(D$3=sale_month,sale_price,0) -> 0 | E13: =IF(E$3=sale_month,sale_price,0) -> 0 | F13: =IF(F$3=sale_month,sale_price,0) -> 0 | G13: =IF(G$3=sale_month,sale_price,0) -> 0 | H13: =IF(H$3=sale_month,sale_price,0) -> 0 | I13: =IF(I$3=sale_month,sale_price,0) -> 0 | ... Z13: =IF(Z$3=sale_month,sale_price,0) -> 0
A14: Расходы на продажу | B14: =IF(B$3=sale_month,-sale_cost,0) -> 0 | C14: =IF(C$3=sale_month,-sale_cost,0) -> 0 | D14: =IF(D$3=sale_month,-sale_cost,0) -> 0 | E14: =IF(E$3=sale_month,-sale_cost,0) -> 0 | F14: =IF(F$3=sale_month,-sale_cost,0) -> 0 | G14: =IF(G$3=sale_month,-sale_cost,0) -> 0 | H14: =IF(H$3=sale_month,-sale_cost,0) -> 0 | I14: =IF(I$3=sale_month,-sale_cost,0) -> 0 | ... Z14: =IF(Z$3=sale_month,-sale_cost,0) -> 0
A15: Поток до налога | B15: =SUM(B5:B14) -> -1292100 | C15: =SUM(C5:C14) -> -26985.1 | D15: =SUM(D5:D14) -> -26985.1 | E15: =SUM(E5:E14) -> -1079 | F15: =SUM(F5:F14) -> -1079 | G15: =SUM(G5:G14) -> -20918.75 | H15: =SUM(H5:H14) -> -575 | I15: =SUM(I5:I14) -> -575 | ... Z15: =SUM(Z5:Z14) -> 0
A16: Накопленный поток | B16: =B15 -> -1292100 | C16: =B16+C15 -> -1319085.1 | D16: =C16+D15 -> -1346070.2 | E16: =D16+E15 -> -1347149.2 | F16: =E16+F15 -> -1348228.2 | G16: =F16+G15 -> -1369146.9 | H16: =G16+H15 -> -1369721.9 | I16: =H16+I15 -> -1370296.9 | J16: =I16+J15 -> -1360403.2 | ... Z16: =Y16+Z15 -> 180364.98
A17: Налог на прибыль | B17: =IF(B$3=sale_month,-vpb,0) -> 0 | C17: =IF(C$3=sale_month,-vpb,0) -> 0 | D17: =IF(D$3=sale_month,-vpb,0) -> 0 | E17: =IF(E$3=sale_month,-vpb,0) -> 0 | F17: =IF(F$3=sale_month,-vpb,0) -> 0 | G17: =IF(G$3=sale_month,-vpb,0) -> 0 | H17: =IF(H$3=sale_month,-vpb,0) -> 0 | I17: =IF(I$3=sale_month,-vpb,0) -> 0 | ... Z17: =IF(Z$3=sale_month,-vpb,0) -> 0
A18: Поток после налога | B18: =B15+B17 -> -1292100 | C18: =C15+C17 -> -26985.1 | D18: =D15+D17 -> -26985.1 | E18: =E15+E17 -> -1079 | F18: =F15+F17 -> -1079 | G18: =G15+G17 -> -20918.75 | H18: =H15+H17 -> -575 | I18: =I15+I17 -> -575 | ... Z18: =Z15+Z17 -> 0

Sheet Аренда
A1: Оценка рыночной аренды по частям здания
A2: Ставки — по предложениям в Хорне, Зваге, Энкхёйзене и Пюрмеренде на funda in business, 16.10.2026
A4: Часть здания | B4: м² VVO | C4: € за м² в год | D4: Аренда в год | E4: Основание ставки
A5: Шоурум, первый этаж | B5: 621 | C5: 80 | D5: =B5*C5 -> 49680 | E5: витрина у въезда в Хорн 80, разрешена торговля; мелкие помещения в промзоне — € 85–100
A6: Шоурум и витрины, антресоль | B6: 228 | C6: 45 | D6: =B6*C6 -> 10260 | E6: второй уровень шоурума, без отдельного входа
A7: Офисы, два этажа | B7: 121 | C7: 110 | D7: =B7*C7 -> 13310 | E7: офисы в деловых районах Хорна — € 120–150
A8: Кантина и подсобные | B8: 52 | C8: 50 | D8: =B8*C8 -> 2600 | E8: вспомогательные помещения
A9: Мастерские и склады, первый этаж | B9: 555 | C9: 62 | D9: =B9*C9 -> 34410 | E9: большие залы в Хорне и окрестностях — € 57–75
A10: Склады и мастерские, второй этаж | B10: 439 | C10: 35 | D10: =B10*C10 -> 15365 | E10: склад на этаже без ворот
A11: Итого | B11: =SUM(B5:B10) -> 2016 | C11: =D11/B11 -> 62.313988 | D11: =SUM(D5:D10) -> 125625
A13: Аренда с учётом сценария | D13: =rent_base*rent_mult -> 125625
A14: К цене продавца | D14: =rent_eff/ask -> 0.0840301
A15: К цене покупки | D15: =rent_eff/buy_price -> 0.10923913

Sheet Сценарии
A1: Сценарии и лестница цены покупки
A2: Рассчитано той же моделью; активный сценарий переключается на листе «Допущения»
A4: Показатель | B4: Пессимистичный | C4: Базовый | D4: Оптимистичный | E4: Ускоренный, 6 месяцев
A5: Аренда в год | B5: 113062.5 | C5: 125625 | D5: 138187.5 | E5: 125625
A6: Доходность для инвестора | B6: 0.09 | C6: 0.0825 | D6: 0.0775 | E6: 0.0825
A7: Месяц начала аренды | B7: 8 | C7: 5 | D7: 4 | E7: 3
A8: Месяц продажи | B8: 15 | C8: 12 | D8: 10 | E8: 6
A9: Цена продажи | B9: 1256250 | C9: 1522727.3 | D9: 1783064.5 | E9: 1576893.9
A10: Все затраты | B10: 1392727.7 | C10: 1394706 | D10: 1398190.6 | E10: 1390925.1
A11: Прибыль до налога | B11: -98790.2 | C11: 180364.98 | D11: 442452.01 | E11: 206906.32
A12: Заработок на € 100 затрат | B12: -7.0932889 | C12: 12.932114 | D12: 31.644613 | E12: 14.875446
A13: Прибыль после налога | B13: -98790.2 | C13: 146095.64 | D13: 341899.39 | E13: 167124.49
A14: Вложено своих денег на пике | B14: 1372224.6 | C14: 1370296.9 | D14: 1370527.3 | E14: 1367563.9
A15: Прибыль на свои деньги после налога | B15: -0.071992735 | C15: 0.10661604 | D15: 0.24946558 | E15: 0.12220597
A16: В пересчёте на год до налога (IRR) | B16: -0.058962123 | C16: 0.13410192 | D16: 0.40799009 | E16: 0.33250138
A17: В пересчёте на год после налога (IRR) | B17: -0.058962123 | C17: 0.10861727 | D17: 0.31323536 | E17: 0.26483397
A20: Лестница цены покупки (базовые допущения)
A21: Цена покупки | B21: Скидка к цене продавца | C21: € за м² VVO | D21: Прибыль, 12 мес. | E21: На € 100 затрат, 12 мес. | F21: В год, 12 мес. | G21: Прибыль, 6 мес. | H21: На € 100 затрат, 6 мес. | I21: В год, 6 мес.
A22: 1495000 | B22: 0 | C22: 741.56746 | D22: -206035.02 | E22: -11.567813 | F22: -0.11902858 | G22: -162411.81 | H22: -9.14227 | I22: -0.1792392
A23: 1400000 | B23: -0.063545151 | C23: 694.44444 | D23: -99635.018 | E23: -5.9494034 | F23: -0.061325106 | G23: -60715.515 | H23: -3.634958 | I23: -0.073523568
A24: 1350000 | B24: -0.096989967 | C24: 669.64286 | D24: -43635.018 | E24: -2.6956728 | F24: -0.027814862 | G24: -7191.1486 | H24: -0.44542602 | I24: -0.009170831
A25: 1300000 | B25: -0.13043478 | C25: 644.84127 | D25: 12364.982 | E25: 0.7912545 | F25: 0.0081734268 | G25: 46333.217 | H25: 2.9728156 | I25: 0.062366284
A26: 1250000 | B26: -0.1638796 | C26: 620.03968 | D26: 68364.982 | E26: 4.5373802 | F26: 0.04692548 | G26: 99857.583 | H26: 6.6452816 | I26: 0.14220927
A27: 1200000 | B27: -0.19732441 | C27: 595.2381 | D27: 124364.98 | E27: 8.572721 | F27: 0.088772742 | G27: 153381.95 | H27: 10.601428 | I27: 0.23170843
A28: 1150000 | B28: -0.23076923 | C28: 570.43651 | D28: 180364.98 | E28: 12.932114 | F28: 0.13410192 | G28: 206906.32 | H28: 14.875446 | I28: 0.33250138
A29: 1100000 | B29: -0.26421405 | C29: 545.63492 | D29: 236364.98 | E29: 17.656227 | F29: 0.183367 | G29: 260430.68 | H29: 19.507249 | I29: 0.44659

Sheet Чувствительность
A1: Чувствительность прибыли до налога
A2: Продажа через 12 месяцев; остальные допущения базовые
A4: Прибыль: цена покупки (строки) и доходность, которую требует инвестор (столбцы)
A5: Цена \ доходность | B5: 0.075 | C5: 0.0775 | D5: 0.08 | E5: 0.0825 | F5: 0.085 | G5: 0.0875 | H5: 0.09
A6: 1100000 | B6: 386734.3 | C6: 333377.45 | D6: 283355.39 | E6: 236364.98 | F6: 192138.71 | G6: 150439.66 | H6: 111057.22
A7: 1150000 | B7: 330734.3 | C7: 277377.45 | D7: 227355.39 | E7: 180364.98 | F7: 136138.71 | G7: 94439.657 | H7: 55057.217
A8: 1200000 | B8: 274734.3 | C8: 221377.45 | D8: 171355.39 | E8: 124364.98 | F8: 80138.712 | G8: 38439.657 | H8: -942.78333
A9: 1250000 | B9: 218734.3 | C9: 165377.45 | D9: 115355.39 | E9: 68364.982 | F9: 24138.712 | G9: -17560.343 | H9: -56942.783
A10: 1300000 | B10: 162734.3 | C10: 109377.45 | D10: 59355.394 | E10: 12364.982 | F10: -31861.288 | G10: -73560.343 | H10: -112942.78
A11: 1400000 | B11: 50734.3 | C11: -2622.5548 | D11: -52644.606 | E11: -99635.018 | F11: -143861.29 | G11: -185560.34 | H11: -224942.78
A12: 1495000 | B12: -55665.7 | C12: -109022.55 | D12: -159044.61 | E12: -206035.02 | F12: -250261.29 | G12: -291960.34 | H12: -331342.78
A15: Прибыль: аренда выше или ниже оценки (строки) и доходность для инвестора (столбцы)
A16: Аренда \ доходность | B16: 0.075 | C16: 0.0775 | D16: 0.08 | E16: 0.0825 | F16: 0.085 | G16: 0.0875 | H16: 0.09
A17: 0.85 | B17: 77599.925 | C17: 32246.598 | D17: -10272.145 | E17: -50213.995 | F17: -87806.325 | G17: -123250.52 | H17: -156725.6
A18: 0.9 | B18: 161978.05 | C18: 113956.88 | D18: 68937.034 | E18: 26645.664 | F18: -13157.979 | G18: -50687.129 | H18: -86131.325
A19: 0.95 | B19: 246356.17 | C19: 195667.16 | D19: 148146.21 | E19: 103505.32 | F19: 61490.366 | G19: 21876.264 | H19: -15537.054
A20: 1 | B20: 330734.3 | C20: 277377.45 | D20: 227355.39 | E20: 180364.98 | F20: 136138.71 | G20: 94439.657 | H20: 55057.217
A21: 1.05 | B21: 415112.42 | C21: 359087.73 | D21: 306564.57 | E21: 257224.64 | F21: 210787.06 | G21: 167003.05 | H21: 125651.49
A22: 1.1 | B22: 499490.55 | C22: 440798.01 | D22: 385773.75 | E22: 334084.3 | F22: 285435.4 | G22: 239566.44 | H22: 196245.76
A23: 1.15 | B23: 583868.68 | C23: 522508.29 | D23: 464982.93 | E23: 410943.96 | F23: 360083.75 | G23: 312129.84 | H23: 266840.03
A26: Месяц начала аренды (строки) × месяц продажи (столбцы)
A27: Аренда \ продажа | B27: 6 | C27: 9 | D27: 12 | E27: 15 | F27: 18
A28: 3 | B28: 206906.32 | C28: 172629.23 | D28: 202310.48 | E28: 231991.73 | F28: 261672.98
A29: 5 | B29: 184960.82 | C29: 150683.73 | D29: 180364.98 | E29: 210046.23 | F29: 239727.48
A30: 7 | C30: 128738.23 | D30: 158419.48 | E30: 188100.73 | F30: 217781.98
A31: 9 | D31: 136473.98 | E31: 166155.23 | F31: 195836.48
A34: Доля экономии покупателя по ст. 13, которую забираем (продажа через 6 мес.)
A35: Доля | B35: 0 | C35: 0.25 | D35: 0.5 | E35: 0.75 | F35: 1
A36: Прибыль до налога | B36: 153416.73 | C36: 180161.52 | D36: 206906.32 | E36: 233651.11 | F36: 260395.9

Sheet План Б
A1: План Б: если быстро продать не получается
A2: Формулы от листов «Допущения», «Аренда» и «Сводка»
A4: Держать сданным
A5: Расходы владельца, % аренды | B5: 0.125 | C5: налог OZB владельца, страховка, ремонт, управление
A6: Кредит под сданное здание, % стоимости | B6: 0 | C6: 0 % — держим без кредита
A7: Чистый доход в год | B7: =rent_eff*(1-hold_opex) -> 109921.88
A8: Вложено всего | B8: =acq_total+capex_total+rent_eff*letting_fee+marketing -> 1364255.9
A9: Чистая доходность на вложенное | B9: =hold_noi/hold_invested -> 0.080572766
A10: Новый кредит | B10: =refi_ltv*value_let -> 0
A11: Проценты в год | B11: =hold_loan*loan_rate -> 0
A12: Капитал после рефинансирования | B12: =hold_invested-hold_loan -> 1364255.9
A13: Денежный поток в год | B13: =hold_noi-hold_int -> 109921.88
A14: Денежная доходность капитала | B14: =hold_cash/hold_eq -> 0.080572766
A15: Разделить на две части и продать пользователям
A16: Цена продажи, € за м² VVO | B16: 850 | C16: Хорн 80: Electronplein 1 — € 922–999, De Marowijne 45 в Зваге — € 1.041
A17: Разделение: нотариус, кадастр, счётчики, противопожарная стена, второй вход | B17: 90000 | C17: оценка
A18: Срок, месяцев | B18: 10
A19: Брокер на продаже, % | B19: 0.02
A20: Выручка | B20: =split_pm2*area_vvo -> 1713600
A21: Расходы на продажу двух частей | B21: =split_gross*split_fee+2*5000 -> 44272
A22: Проценты за срок | B22: =loan*loan_rate*split_months/12 -> 0
A23: Содержание и простой за срок | B23: =(buy_price*holding_pct+void_m2*area_vvo)*split_months/12 -> 10790
A24: Все затраты | B24: =acq_total+capex_total+split_cost+split_int+split_hold+split_sale_cost -> 1488974.2
A25: Прибыль до налога | B25: =split_gross-split_total -> 224625.8
A26: Маржа на затраты | B26: =(split_gross-split_total)/split_total -> 0.15085943

Sheet Конкуренты
A1: Сопоставимые объекты: Хорн и Западная Фрисландия
A2: funda in business, выгрузка через Scrapling 16.10.2026
A4: Продажа пустых зданий от 400 м²
A5: Адрес | B5: Город | C5: м² | D5: Цена | E5: € за м² | F5: Год | G5: Статус | H5: На продаже | I5: Ссылка
A6: Kernweg 6 | B6: Хорн | C6: 11195 | D6: 5700000 | E6: 509 | F6: 1960-1970 | G6: Beschikbaar | H6: 6+ maanden | I6: https://www.fundainbusiness.nl/bedrijfshal/hoorn-nh/object-89466410-kernweg-6/
A7: Protonweg 13 | B7: Хорн | C7: 1737 | D7: 900000 | E7: 518 | F7: 1971-1980 | G7: Onder bod | H7: 6+ maanden | I7: https://www.fundainbusiness.nl/bedrijfshal/hoorn-nh/object-89466418-protonweg-13/
A8: Neutronweg 7 | B8: Хорн | C8: 11289 | D8: 6500000 | E8: 576 | F8: 1971-1980 | G8: Beschikbaar | H8: 6+ maanden | I8: https://www.fundainbusiness.nl/bedrijfshal/hoorn-nh/object-89466413-neutronweg-7/
A9: Electronweg 19-23 | B9: Хорн | C9: 4220 | D9: 2795000 | E9: 662 | F9: 1978 | G9: Beschikbaar | H9: 6+ maanden | I9: https://www.fundainbusiness.nl/bedrijfshal/hoorn-nh/object-43274830-electronweg-19-23/
A10: Kernweg 1 | B10: Хорн | C10: 2155 | D10: 1495000 | E10: 694 | F10: 2007 | G10: Beschikbaar | H10: 6+ maanden | I10: https://www.fundainbusiness.nl/bedrijfshal/hoorn-nh/object-43955233-kernweg-1/
A11: Schelphorst 4 | B11: Вирингерверф | C11: 694 | D11: 575000 | E11: 829 | F11: 1993 | G11: Beschikbaar | H11: 6+ maanden | I11: https://www.fundainbusiness.nl/bedrijfshal/wieringerwerf/object-43142682-schelphorst-4/
A12: Electronplein 1 | B12: Хорн | C12: 4500 | D12: 3750000 | E12: 833 | F12: 1999 | G12: Beschikbaar | H12: 6+ maanden | I12: https://www.fundainbusiness.nl/bedrijfshal/hoorn-nh/object-43095324-electronplein-1/
A13: Electronplein 1 | B13: Хорн | C13: 1625 | D13: 1499000 | E13: 922 | F13: 1999 | G13: Beschikbaar | H13: 3 weken | I13: https://www.fundainbusiness.nl/bedrijfshal/hoorn-nh/object-44510584-electronplein-1/
A14: De Star 5-a | B14: Энкхёйзен | C14: 936 | D14: 875000 | E14: 935 | F14: 2023 | G14: Beschikbaar | H14: 6 weken | I14: https://www.fundainbusiness.nl/bedrijfshal/enkhuizen/object-44585555-de-star-5-a/
A15: Electronplein 1 | B15: Хорн | C15: 1100 | D15: 1099000 | E15: 999 | F15: 1999 | G15: Beschikbaar | H15: 3 weken | I15: https://www.fundainbusiness.nl/bedrijfshal/hoorn-nh/object-44504456-electronplein-1/
A16: Kernweg 4 | B16: Хорн | C16: 11976 | D16: 12000000 | E16: 1002 | F16: 1971-1980 | G16: Beschikbaar | H16: 6+ maanden | I16: https://www.fundainbusiness.nl/bedrijfshal/hoorn-nh/object-89466524-kernweg-4/
A17: De Marowijne 45 | B17: Зваг | C17: 2258 | D17: 2350000 | E17: 1041 | F17: 2004 | G17: Beschikbaar | H17: 4 maanden | I17: https://www.fundainbusiness.nl/bedrijfshal/zwaag/object-80854248-de-marowijne-45/
... A35: Herculesstraat 57 | B35: Алкмар | C35: 460 | D35: 800000 | E35: 1739 | F35: 1960 | G35: Beschikbaar | H35: 6+ maanden | I35: https://www.fundainbusiness.nl/bedrijfshal/alkmaar/object-43802000-herculesstraat-57/
A37: Аренда залов от 300 м²
A38: Адрес | B38: Город | C38: м² | D38: € за м² в год | E38: В год | F38: Год | H38: На рынке | I38: Ссылка
A39: Koraalstraat 1 | B39: Алкмар | C39: 12137 | D39: 49.4 | E39: 599567.8 | F39: 1996 | H39: 6+ maanden | I39: https://www.fundainbusiness.nl/bedrijfshal/alkmaar/object-43318885-koraalstraat-1/
A40: Fluorietweg 29 | B40: Алкмар | C40: 8583 | D40: 87.4 | E40: 750154.2 | F40: 2010 | H40: 6+ maanden | I40: https://www.fundainbusiness.nl/bedrijfshal/alkmaar/object-43203349-fluorietweg-29/
A41: Electronplein 1 | B41: Хорн | C41: 5180 | D41: 56.8 | E41: 294224 | F41: 1999 | H41: 6+ maanden | I41: https://www.fundainbusiness.nl/bedrijfshal/hoorn-nh/object-43246991-electronplein-1/
A42: Westrak 208 | B42: Вирингерверф | C42: 4676 | D42: 61.6 | E42: 288041.6 | F42: 2006 | H42: 6+ maanden | I42: https://www.fundainbusiness.nl/bedrijfshal/wieringerwerf/object-42189263-westrak-208/
A43: Westrak 208 | B43: Вирингерверф | C43: 2900 | D43: 60 | E43: 174000 | F43: 2006 | H43: 2 weken | I43: https://www.fundainbusiness.nl/bedrijfshal/wieringerwerf/object-44528013-westrak-208/
A44: De Factorij 40 | B44: Зваг | C44: 2710 | D44: 75.3 | E44: 204063 | F44: 1999 | H44: 8 weken | I44: https://www.fundainbusiness.nl/bedrijfshal/zwaag/object-44560899-de-factorij-40/
A45: Jelle Zijlstraweg 69 | B45: Зваг | C45: 2695 | D45: 70.1 | E45: 188919.5 | F45: 2021 | H45: 6 weken | I45: https://www.fundainbusiness.nl/bedrijfshal/zwaag/object-44589122-jelle-zijlstraweg-69/
A46: Westrak 208 | B46: Вирингерверф | C46: 1776 | D46: 64.2 | E46: 114019.2 | F46: 2006 | H46: 2 weken | I46: https://www.fundainbusiness.nl/bedrijfshal/wieringerwerf/object-44528014-westrak-208/
A47: Hazenkoog 2 | B47: Алкмар | C47: 1713 | D47: 57.4 | E47: 98326.2 | F47: 1991 | H47: 6+ maanden | I47: https://www.fundainbusiness.nl/bedrijfshal/alkmaar/object-43714147-hazenkoog-2/
A48: Visserijweg 67 | B48: Пюрмеренд | C48: 1485 | D48: 75.1 | E48: 111523.5 | F48: 2025 | H48: 6+ maanden | I48: https://www.fundainbusiness.nl/bedrijfshal/purmerend/object-43316575-visserijweg-67/
A49: Boomkorstraat 4 | B49: Пюрмеренд | C49: 1413 | D49: 78.6 | E49: 111061.8 | F49: 2022 | H49: 2 maanden | I49: https://www.fundainbusiness.nl/bedrijfshal/purmerend/object-44558293-boomkorstraat-4/
A50: Newtonstraat 44 | B50: Херхюговард | C50: 1308 | D50: 82.6 | E50: 108040.8 | F50: 2004 | H50: 2 oktober 2026 | I50: https://www.fundainbusiness.nl/bedrijfshal/heerhugowaard/object-44522402-newtonstraat-44/
... A73: de Oude Veiling 25-H | B73: Зваг | C73: 300 | D73: 78 | E73: 23400 | F73: 2024 | H73: 2 maanden | I73: https://www.fundainbusiness.nl/bedrijfshal/zwaag/object-44446876-de-oude-veiling-25-h/
A75: Сданные объекты на продаже — доходность покупателя (k.k.)
A76: Адрес | B76: Город | C76: м² | D76: Цена | E76: Аренда в год | F76: Доходность | G76: Год | H76: На продаже | I76: Ссылка
A77: Boterstraat 21 | B77: Алкмар | C77: 188 | D77: 450000 | E77: 37500 | F77: 0.0833 | G77: 1900 | H77: 5 weken | I77: https://www.fundainbusiness.nl/belegging/alkmaar/object-44581679-boterstraat-21/
A78: Atoomweg 12 | B78: Хорн | C78: 583 | D78: 575000 | E78: 51096 | F78: 0.0889 | G78: 1972 | H78: 6+ maanden | I78: https://www.fundainbusiness.nl/belegging/hoorn-nh/object-43363688-atoomweg-12/
A79: Kamerlingh Onnesstraat 27-B | B79: Алкмар | C79: 190 | D79: 395000 | E79: 36933 | F79: 0.0935 | G79: 2006 | H79: 6+ maanden | I79: https://www.fundainbusiness.nl/belegging/alkmaar/object-43201526-kamerlingh-onnesstraat-27-b/
A80: Neutronweg 3 | B80: Хорн | C80: 2117 | D80: 1650000 | E80: 141000 | F80: 0.0855 | G80: около 1978 | H80: снят с продажи | I80: https://www.fundainbusiness.nl/belegging/hoorn-nh/object-43660627-neutronweg-3/
A82: Другие здания по той же схеме: купить по цене продавца, сдать, продать через 12 месяцев
A83: Объект | B83: Цена продавца | C83: Аренда в год, оценка | D83: Доходность для инвестора | E83: Итог по цене продавца | F83: Сбить цену, чтобы выйти в ноль | G83: Сбить цену ради € 10 на € 100 затрат | H83: Цена для € 10 на € 100 затрат
...

Sheet Источники
A1: Источники и правила
A4: Объект | B4: https://www.fundainbusiness.nl/bedrijfshal/hoorn-nh/object-43955233-kernweg-1/ — € 1.495.000 k.k., на продаже больше 6 месяцев
A5: Налог на передачу | B5: Wet op belastingen van rechtsverkeer, ст. 14: 10,4 % для нежилой недвижимости (редакции 2026-01-01 и 2027-01-01)
A6: Перепродажа до 6 месяцев | B6: Там же, ст. 13: при покупке в течение 6 месяцев после предыдущей покупки база уменьшается на сумму, с которой налог уже уплачен
A7: Налог на прибыль | B7: VPB 2026: 19 % до € 200.000, 25,8 % сверх (KVK)
A8: Ставка кредита | B8: в модели не используется; Euribor 3M 2,628 % на 14.10.2026 (euribor-rates.eu) — на случай кредита
A9: Рынок | B9: NVM, бизнес-недвижимость, 2-й квартал 2026: спрос в Северной Голландии за полугодие на уровне прошлого года, предложение 5 % фонда
A10: Рынок | B10: Cushman & Wakefield, 2-й квартал 2026: на второстепенных локациях — пустующие площади и уступки арендаторам
A11: Рынок | B11: JLL, лёгкая промышленность, 2-й квартал 2026: спрос за полугодие 887.200 м², в основном небольшие помещения, пустует 2,2 %
A12: Сопоставимые объекты | B12: funda in business: Хорн, Зваг, Энкхёйзен, Вогнюм, Медемблик, Пюрмеренд, Херхюговард, Алкмар; выгрузка Scrapling 16.10.2026
