Workbook
Name ask: 'Допущения'!$B$5
Name buy_price: 'Допущения'!$B$6
Name area_m2: 'Допущения'!$B$7
Name vat_route: 'Допущения'!$B$8
Name ovb: 'Допущения'!$B$9
Name vat_rate: 'Допущения'!$B$10
Name vat_refund_month: 'Допущения'!$B$11
Name notary: 'Допущения'!$B$12
Name dd: 'Допущения'!$B$13
Name valuation: 'Допущения'!$B$14
Name advisory: 'Допущения'!$B$15
Name capex_m2: 'Допущения'!$B$17
Name capex_fixed: 'Допущения'!$B$18
Name capex_vat: 'Допущения'!$B$19
Name capex_months: 'Допущения'!$B$20
Name letting_fee: 'Допущения'!$B$22
Name marketing: 'Допущения'!$B$23
Name holding_pct: 'Допущения'!$B$25
Name hold_fixed: 'Допущения'!$B$26
Name void_m2: 'Допущения'!$B$27
Name ltv: 'Допущения'!$B$29
Name loan_rate: 'Допущения'!$B$30
Name bank_fee: 'Допущения'!$B$31
Name sale_fee: 'Допущения'!$B$33
Name sale_fixed: 'Допущения'!$B$34
Name vat_window: 'Допущения'!$B$35
Name late_ovb: 'Допущения'!$B$36
Name art13_share: 'Допущения'!$B$37
Name vpb_low: 'Допущения'!$B$39
Name vpb_high: 'Допущения'!$B$40
Name vpb_step: 'Допущения'!$B$41
Name rent_mult: 'Допущения'!$B$45
Name exit_bar: 'Допущения'!$B$46
Name lease_month: 'Допущения'!$B$47
Name rent_free: 'Допущения'!$B$48
Name sale_month: 'Допущения'!$B$49
Name scenario: 'Допущения'!$B$50
Name rent_base: 'Аренда'!$D$7
Name rent_eff: 'Аренда'!$D$9
Name acq_price: 'Сводка'!$B$5
Name acq_total: 'Сводка'!$B$12
Name vat_paid: 'Сводка'!$B$13
Name loan: 'Сводка'!$B$14
Name capex_total: 'Сводка'!$B$15
Name first_paid: 'Сводка'!$B$18
Name late: 'Сводка'!$B$19
Name value_let: 'Сводка'!$B$20
Name free_left: 'Сводка'!$B$21
Name uplift: 'Сводка'!$B$22
Name sale_price: 'Сводка'!$B$23
Name sale_cost: 'Сводка'!$B$24
Name income: 'Сводка'!$B$26
Name cost_total: 'Сводка'!$B$27
Name profit: 'Сводка'!$B$28
Name vpb: 'Сводка'!$B$30
Name equity: 'Сводка'!$B$32
Name buyer_ovb: 'Сводка'!$B$38
Name buyer_total: 'Сводка'!$B$39
Name hold_opex: 'План Б'!$B$5
Name hold_noi: 'План Б'!$B$6

Sheet Сводка
A1: Флип-модель: Boeingavenue 307-N, Схипхол-Рейк — сводка
A2: Купить новый юнит за свои средства → отделать → сдать → продать сданным инвестору до конца 6 месяцев после начала аренды. Все цифры — формулы от листов «Допущения» и «Аренда».
A4: Покупка
A5: Цена покупки | B5: =buy_price
A6: Налог на передачу | B6: =buy_price*ovb
A7: Нотариус и кадастр | B7: =notary
A8: Проверка объекта | B8: =dd
A9: Оценка для банка | B9: =IF(ltv>0,valuation,0)
A10: Консультант по покупке | B10: =buy_price*advisory
A11: Комиссия банка | B11: =loan*bank_fee
A12: Итого на покупку | B12: =SUM(B5:B11)
A13: НДС с цены: платим у нотариуса и возвращаем | B13: =IF(vat_route=1,buy_price*vat_rate,0) | C13: в затраты не входит, но занимает деньги до возврата
A14: Кредит | B14: =buy_price*ltv
A15: Отделка | B15: =(capex_m2*area_m2+capex_fixed)*(1+capex_vat)
A16: Продажа
A17: Аренда в год (сценарий) | B17: =rent_eff
A18: Первый оплачиваемый месяц | B18: =lease_month+rent_free
A19: Продажа позже срока без налога 10,4 % (1 — да) | B19: =IF(AND(vat_route=1,sale_month>lease_month-1+vat_window),1,0) | C19: акт у нотариуса позже 6 месяцев после начала аренды: инвестор платит налог и снижает цену
A20: Стоимость сданного помещения: аренда / доходность для инвестора | B20: =rent_eff/exit_bar/IF(late=1,1+late_ovb,1)
A21: Минус не закончившиеся месяцы без платы | B21: =MAX(0,first_paid-1-sale_month)*rent_eff/12
A22: Плюс доля экономии покупателя по ст. 13 | B22: =IF(AND(vat_route=0,sale_month<=6),art13_share*ovb*buy_price/(1+ovb),0)
A23: Цена продажи | B23: =value_let-free_left+uplift | C23: продажа сданного помещения инвестору с НДС, который он возвращает
A24: Расходы на продажу | B24: =sale_price*sale_fee+sale_fixed
A25: Результат
A26: Доходы: аренда за период и продажа | B26: =SUM('Денежный поток'!B11:Z11)+SUM('Денежный поток'!B14:Z14)
A27: Все затраты (НДС возвращается и не входит) | B27: =-(SUM('Денежный поток'!B5:Z5)+SUM('Денежный поток'!B7:Z10)+SUM('Денежный поток'!B12:Z12)+SUM('Денежный поток'!B15:Z15))
A28: Прибыль до налога | B28: =SUM('Денежный поток'!B16:Z16)
A29: Заработок на каждые € 100 затрат | B29: =profit/cost_total*100 | C29: прибыль до налога, делённая на все затраты
A30: Налог на прибыль VPB | B30: =IF(profit<=0,0,MIN(profit,vpb_step)*vpb_low+MAX(0,profit-vpb_step)*vpb_high)
A31: Прибыль после налога | B31: =profit-vpb
A32: Вложено своих денег на пике | B32: =-MIN('Денежный поток'!B17:Z17) | C32: сколько денег занято в проекте в самый затратный момент, включая НДС до возврата
A33: Прибыль на свои деньги после налога | B33: =(profit-vpb)/equity
A34: В пересчёте на год (IRR), до налога | B34: =(1+IRR('Денежный поток'!B16:Z16,0.01))^12-1 | C34: учитывает, сколько месяцев деньги заняты в проекте
A35: В пересчёте на год (IRR), после налога | B35: =(1+IRR('Денежный поток'!B19:Z19,0.01))^12-1
A36: Сколько вернётся на € 1 своих денег, после налога | B36: =(equity+profit-vpb)/equity
A37: Глазами инвестора
A38: Налог на передачу, который платит инвестор | B38: =IF(vat_route=1,IF(late=1,late_ovb*sale_price,0),IF(sale_month<=6,ovb*(sale_price-buy_price),ovb*sale_price))
A39: Его полная цена | B39: =sale_price+buyer_ovb
A40: Его доходность на все расходы | B40: =rent_eff/buyer_total
A42: Потолок цены покупки (подбор моделью, базовые допущения)
...

Sheet Допущения
A1: Флип-модель: Boeingavenue 307-N, Схипхол-Рейк — допущения
A2: Синие значения на жёлтом фоне можно менять: все листы пересчитаются. Суммы без НДС, евро.
A4: Покупка
A5: Цена продавца (vrij op naam, без НДС) | B5: 360000 | H5: funda in business, 20.10.2026
A6: Цена покупки — наше предложение | B6: 300000 | H6: 17 % ниже цены продавца; потолок без убытка — на листе «Сводка»
A7: Площадь, м² | B7: 193 | H7: 193 м² на двух этажах по 96,5 м²
A8: Схема с НДС: 1 — новое помещение, 0 — обычная покупка | B8: 1 | H8: ст. 15 WBR: новое здание продаётся с НДС и без налога на передачу
A9: Налог на передачу при нашей покупке | B9: 0 | H9: 0 % — схема с НДС
A10: НДС с цены покупки | B10: 0.21 | H10: платим у нотариуса, возвращаем декларацией
A11: Месяц возврата НДС | B11: 2
A12: Нотариус и кадастр | B12: 0 | H12: в цене vrij op naam
A13: Проверка объекта и договора | B13: 3000 | H13: оценка
A14: Оценка для банка | B14: 3500 | H14: только при кредите
A15: Консультант по покупке, % цены | B15: 0.01 | H15: оценка
A16: Отделка под арендатора
A17: Отделка, € на м² | B17: 200 | H17: голая коробка: электрическое тепло, свет, туалет, кухня, пожарная защита
A18: Отделка, резерв | B18: 5000
A19: НДС на отделку как расход | B19: 0 | H19: 0 %: аренда с НДС, НДС на работы возвращается
A20: Месяцев на отделку | B20: 2
A21: Сдача в аренду
A22: Брокер по аренде, % годовой аренды | B22: 0.15
A23: Реклама и показы | B23: 1500
A24: Содержание
A25: Налог OZB, страховка, ремонт: % цены в год | B25: 0.006
A26: Постоянные платежи владельца, € в год | B26: 1000 | H26: взносы за общий двор и парковку
A27: Энергия и охрана в простое, € на м² в год | B27: 3
A28: Кредит — по умолчанию не используется: покупка за свои средства
A29: Кредит, доля цены покупки | B29: 0 | H29: 0 % — покупка за свои средства
A30: Ставка кредита | B30: 0.05128 | H30: только если включить кредит
A31: Комиссия банка, % кредита | B31: 0.01 | H31: только если включить кредит
A32: Продажа
A33: Брокер на продаже, % цены | B33: 0.0125
A34: Юрист и реклама продажи | B34: 2500
A35: Срок продажи без налога 10,4 % для инвестора, месяцев после начала аренды | B35: 6 | H35: ст. 15 WBR; аренда начинается в начале месяца въезда
A36: Налог на передачу для инвестора при поздней продаже | B36: 0.104 | H36: инвестор снижает цену на эту сумму
A37: Доля экономии покупателя по ст. 13 WBR, которую забираем в цене | B37: 0.5 | H37: только для обычной покупки и продажи до 6 месяцев
A38: Налог на прибыль (VPB) 2026
A39: Ставка до порога | B39: 0.19 | H39: KVK, 2026
A40: Ставка выше порога | B40: 0.258
A41: Порог | B41: 200000
...

Sheet Денежный поток
A1: Денежный поток по месяцам
A2: Месяц 0 — акт у нотариуса и оплата; продажа — в месяц продажи
A3: Месяц | B3: 0 | C3: 1 | D3: 2 | E3: 3 | F3: 4 | G3: 5 | H3: 6 | I3: 7 | J3: 8 | K3: 9 | L3: 10 | M3: 11 | N3: 12 | O3: 13 | P3: 14 | Q3: 15 | R3: 16 | S3: 17 | T3: 18 | U3: 19 | V3: 20 | W3: 21 | X3: 22 | Y3: 23 | Z3: 24
A4: В работе (до продажи) | B4: =IF(B$3<=sale_month,1,0) | C4: =IF(C$3<=sale_month,1,0) | D4: =IF(D$3<=sale_month,1,0) | E4: =IF(E$3<=sale_month,1,0) | F4: =IF(F$3<=sale_month,1,0) | G4: =IF(G$3<=sale_month,1,0) | H4: =IF(H$3<=sale_month,1,0) | I4: =IF(I$3<=sale_month,1,0) | ... Z4: =IF(Z$3<=sale_month,1,0)
A5: Покупка и расходы на сделку | B5: =IF(B$3=0,-acq_total,0) | C5: =IF(C$3=0,-acq_total,0) | D5: =IF(D$3=0,-acq_total,0) | E5: =IF(E$3=0,-acq_total,0) | F5: =IF(F$3=0,-acq_total,0) | G5: =IF(G$3=0,-acq_total,0) | H5: =IF(H$3=0,-acq_total,0) | I5: =IF(I$3=0,-acq_total,0) | ... Z5: =IF(Z$3=0,-acq_total,0)
A6: НДС с цены: оплата и возврат | B6: =IF(B$3=0,-vat_paid,0)+IF(B$3=MIN(vat_refund_month,sale_month),vat_paid,0) | C6: =IF(C$3=0,-vat_paid,0)+IF(C$3=MIN(vat_refund_month,sale_month),vat_paid,0) | D6: =IF(D$3=0,-vat_paid,0)+IF(D$3=MIN(vat_refund_month,sale_month),vat_paid,0) | E6: =IF(E$3=0,-vat_paid,0)+IF(E$3=MIN(vat_refund_month,sale_month),vat_paid,0) | F6: =IF(F$3=0,-vat_paid,0)+IF(F$3=MIN(vat_refund_month,sale_month),vat_paid,0) | G6: =IF(G$3=0,-vat_paid,0)+IF(G$3=MIN(vat_refund_month,sale_month),vat_paid,0) | H6: =IF(H$3=0,-vat_paid,0)+IF(H$3=MIN(vat_refund_month,sale_month),vat_paid,0) | I6: =IF(I$3=0,-vat_paid,0)+IF(I$3=MIN(vat_refund_month,sale_month),vat_paid,0) | ... Z6: =IF(Z$3=0,-vat_paid,0)+IF(Z$3=MIN(vat_refund_month,sale_month),vat_paid,0)
A7: Отделка | B7: =IF(AND(B$3>=1,B$3<=capex_months,B$3<=sale_month),-capex_total/capex_months,0) | C7: =IF(AND(C$3>=1,C$3<=capex_months,C$3<=sale_month),-capex_total/capex_months,0) | D7: =IF(AND(D$3>=1,D$3<=capex_months,D$3<=sale_month),-capex_total/capex_months,0) | E7: =IF(AND(E$3>=1,E$3<=capex_months,E$3<=sale_month),-capex_total/capex_months,0) | F7: =IF(AND(F$3>=1,F$3<=capex_months,F$3<=sale_month),-capex_total/capex_months,0) | G7: =IF(AND(G$3>=1,G$3<=capex_months,G$3<=sale_month),-capex_total/capex_months,0) | H7: =IF(AND(H$3>=1,H$3<=capex_months,H$3<=sale_month),-capex_total/capex_months,0) | I7: =IF(AND(I$3>=1,I$3<=capex_months,I$3<=sale_month),-capex_total/capex_months,0) | ... Z7: =IF(AND(Z$3>=1,Z$3<=capex_months,Z$3<=sale_month),-capex_total/capex_months,0)
A8: Содержание | B8: =IF(AND(B$3>=1,B$3<=sale_month),-buy_price*holding_pct/12-hold_fixed/12,0) | C8: =IF(AND(C$3>=1,C$3<=sale_month),-buy_price*holding_pct/12-hold_fixed/12,0) | D8: =IF(AND(D$3>=1,D$3<=sale_month),-buy_price*holding_pct/12-hold_fixed/12,0) | E8: =IF(AND(E$3>=1,E$3<=sale_month),-buy_price*holding_pct/12-hold_fixed/12,0) | F8: =IF(AND(F$3>=1,F$3<=sale_month),-buy_price*holding_pct/12-hold_fixed/12,0) | G8: =IF(AND(G$3>=1,G$3<=sale_month),-buy_price*holding_pct/12-hold_fixed/12,0) | H8: =IF(AND(H$3>=1,H$3<=sale_month),-buy_price*holding_pct/12-hold_fixed/12,0) | I8: =IF(AND(I$3>=1,I$3<=sale_month),-buy_price*holding_pct/12-hold_fixed/12,0) | ... Z8: =IF(AND(Z$3>=1,Z$3<=sale_month),-buy_price*holding_pct/12-hold_fixed/12,0)
A9: Энергия и охрана в простое | B9: =IF(AND(B$3>=1,B$3<lease_month,B$3<=sale_month),-void_m2*area_m2/12,0) | C9: =IF(AND(C$3>=1,C$3<lease_month,C$3<=sale_month),-void_m2*area_m2/12,0) | D9: =IF(AND(D$3>=1,D$3<lease_month,D$3<=sale_month),-void_m2*area_m2/12,0) | E9: =IF(AND(E$3>=1,E$3<lease_month,E$3<=sale_month),-void_m2*area_m2/12,0) | F9: =IF(AND(F$3>=1,F$3<lease_month,F$3<=sale_month),-void_m2*area_m2/12,0) | G9: =IF(AND(G$3>=1,G$3<lease_month,G$3<=sale_month),-void_m2*area_m2/12,0) | H9: =IF(AND(H$3>=1,H$3<lease_month,H$3<=sale_month),-void_m2*area_m2/12,0) | I9: =IF(AND(I$3>=1,I$3<lease_month,I$3<=sale_month),-void_m2*area_m2/12,0) | ... Z9: =IF(AND(Z$3>=1,Z$3<lease_month,Z$3<=sale_month),-void_m2*area_m2/12,0)
A10: Сдача: брокер и реклама | B10: =IF(AND(B$3>=1,B$3=lease_month,B$3<=sale_month),-(rent_eff*letting_fee+marketing),0) | C10: =IF(AND(C$3>=1,C$3=lease_month,C$3<=sale_month),-(rent_eff*letting_fee+marketing),0) | D10: =IF(AND(D$3>=1,D$3=lease_month,D$3<=sale_month),-(rent_eff*letting_fee+marketing),0) | E10: =IF(AND(E$3>=1,E$3=lease_month,E$3<=sale_month),-(rent_eff*letting_fee+marketing),0) | F10: =IF(AND(F$3>=1,F$3=lease_month,F$3<=sale_month),-(rent_eff*letting_fee+marketing),0) | G10: =IF(AND(G$3>=1,G$3=lease_month,G$3<=sale_month),-(rent_eff*letting_fee+marketing),0) | H10: =IF(AND(H$3>=1,H$3=lease_month,H$3<=sale_month),-(rent_eff*letting_fee+marketing),0) | I10: =IF(AND(I$3>=1,I$3=lease_month,I$3<=sale_month),-(rent_eff*letting_fee+marketing),0) | ... Z10: =IF(AND(Z$3>=1,Z$3=lease_month,Z$3<=sale_month),-(rent_eff*letting_fee+marketing),0)
A11: Аренда | B11: =IF(AND(B$3>=1,B$3>=first_paid,B$3<=sale_month),rent_eff/12,0) | C11: =IF(AND(C$3>=1,C$3>=first_paid,C$3<=sale_month),rent_eff/12,0) | D11: =IF(AND(D$3>=1,D$3>=first_paid,D$3<=sale_month),rent_eff/12,0) | E11: =IF(AND(E$3>=1,E$3>=first_paid,E$3<=sale_month),rent_eff/12,0) | F11: =IF(AND(F$3>=1,F$3>=first_paid,F$3<=sale_month),rent_eff/12,0) | G11: =IF(AND(G$3>=1,G$3>=first_paid,G$3<=sale_month),rent_eff/12,0) | H11: =IF(AND(H$3>=1,H$3>=first_paid,H$3<=sale_month),rent_eff/12,0) | I11: =IF(AND(I$3>=1,I$3>=first_paid,I$3<=sale_month),rent_eff/12,0) | ... Z11: =IF(AND(Z$3>=1,Z$3>=first_paid,Z$3<=sale_month),rent_eff/12,0)
A12: Проценты | B12: =IF(AND(B$3>=1,B$3<=sale_month),-loan*loan_rate/12,0) | C12: =IF(AND(C$3>=1,C$3<=sale_month),-loan*loan_rate/12,0) | D12: =IF(AND(D$3>=1,D$3<=sale_month),-loan*loan_rate/12,0) | E12: =IF(AND(E$3>=1,E$3<=sale_month),-loan*loan_rate/12,0) | F12: =IF(AND(F$3>=1,F$3<=sale_month),-loan*loan_rate/12,0) | G12: =IF(AND(G$3>=1,G$3<=sale_month),-loan*loan_rate/12,0) | H12: =IF(AND(H$3>=1,H$3<=sale_month),-loan*loan_rate/12,0) | I12: =IF(AND(I$3>=1,I$3<=sale_month),-loan*loan_rate/12,0) | ... Z12: =IF(AND(Z$3>=1,Z$3<=sale_month),-loan*loan_rate/12,0)
A13: Кредит: получен / погашен | B13: =IF(B$3=0,loan,0)-IF(B$3=sale_month,loan,0) | C13: =IF(C$3=0,loan,0)-IF(C$3=sale_month,loan,0) | D13: =IF(D$3=0,loan,0)-IF(D$3=sale_month,loan,0) | E13: =IF(E$3=0,loan,0)-IF(E$3=sale_month,loan,0) | F13: =IF(F$3=0,loan,0)-IF(F$3=sale_month,loan,0) | G13: =IF(G$3=0,loan,0)-IF(G$3=sale_month,loan,0) | H13: =IF(H$3=0,loan,0)-IF(H$3=sale_month,loan,0) | I13: =IF(I$3=0,loan,0)-IF(I$3=sale_month,loan,0) | ... Z13: =IF(Z$3=0,loan,0)-IF(Z$3=sale_month,loan,0)
A14: Продажа | B14: =IF(B$3=sale_month,sale_price,0) | C14: =IF(C$3=sale_month,sale_price,0) | D14: =IF(D$3=sale_month,sale_price,0) | E14: =IF(E$3=sale_month,sale_price,0) | F14: =IF(F$3=sale_month,sale_price,0) | G14: =IF(G$3=sale_month,sale_price,0) | H14: =IF(H$3=sale_month,sale_price,0) | I14: =IF(I$3=sale_month,sale_price,0) | ... Z14: =IF(Z$3=sale_month,sale_price,0)
A15: Расходы на продажу | B15: =IF(B$3=sale_month,-sale_cost,0) | C15: =IF(C$3=sale_month,-sale_cost,0) | D15: =IF(D$3=sale_month,-sale_cost,0) | E15: =IF(E$3=sale_month,-sale_cost,0) | F15: =IF(F$3=sale_month,-sale_cost,0) | G15: =IF(G$3=sale_month,-sale_cost,0) | H15: =IF(H$3=sale_month,-sale_cost,0) | I15: =IF(I$3=sale_month,-sale_cost,0) | ... Z15: =IF(Z$3=sale_month,-sale_cost,0)
A16: Поток до налога | B16: =SUM(B5:B15) | C16: =SUM(C5:C15) | D16: =SUM(D5:D15) | E16: =SUM(E5:E15) | F16: =SUM(F5:F15) | G16: =SUM(G5:G15) | H16: =SUM(H5:H15) | I16: =SUM(I5:I15) | ... Z16: =SUM(Z5:Z15)
A17: Накопленный поток | B17: =B16 | C17: =B17+C16 | D17: =C17+D16 | E17: =D17+E16 | F17: =E17+F16 | G17: =F17+G16 | H17: =G17+H16 | I17: =H17+I16 | J17: =I17+J16 | ... Z17: =Y17+Z16
A18: Налог на прибыль | B18: =IF(B$3=sale_month,-vpb,0) | C18: =IF(C$3=sale_month,-vpb,0) | D18: =IF(D$3=sale_month,-vpb,0) | E18: =IF(E$3=sale_month,-vpb,0) | F18: =IF(F$3=sale_month,-vpb,0) | G18: =IF(G$3=sale_month,-vpb,0) | H18: =IF(H$3=sale_month,-vpb,0) | I18: =IF(I$3=sale_month,-vpb,0) | ... Z18: =IF(Z$3=sale_month,-vpb,0)
A19: Поток после налога | B19: =B16+B18 | C19: =C16+C18 | D19: =D16+D18 | E19: =E16+E18 | F19: =F16+F18 | G19: =G16+G18 | H19: =H16+H18 | I19: =I16+I18 | ... Z19: =Z16+Z18

Sheet Аренда
A1: Аренда по частям помещения
A2: Ставки — по объявлениям на funda in business, 20.10.2026; без НДС
A4: Часть | B4: м² | C4: € за м² в год | D4: Аренда в год | E4: Основание ставки
A5: Производственное помещение, первый этаж, высота 3,7 м | B5: 96.5 | C5: 135 | D5: =B5*C5 | E5: ворота, пол до 2.000 кг/м²
A6: Офис или мастерская, второй этаж, высота 3 м | B6: 96.5 | C6: 165 | D6: =B6*C6 | E6: юниты 307-P и 307-R — € 159 и € 176
A7: Итого | B7: =SUM(B5:B6) | C7: =D7/B7 | D7: =SUM(D5:D6)
A9: Аренда с учётом сценария | D9: =rent_base*rent_mult
A10: К цене продавца | D10: =rent_eff/ask
A11: К цене покупки | D11: =rent_eff/buy_price
A14: Аренда новых бизнес-юнитов у Схипхол-Рейка, € за м² в год
A15: Объект | C15: € за м² в год | E15: Что за помещение
A16: Boeingavenue 303-F, Схипхол-Рейк | C16: 211.1 | E16: 108 м², 2026
A17: Boeingavenue 307-R, тот же проект | C17: 175.7 | E17: 140 м², 2025
A18: Lakenblekerstraat 21-A1, Алсмер | C18: 166.7 | E18: 216 м², 2025
A19: Boeingavenue 307-P, тот же проект | C19: 158.6 | E19: 140 м², 2025
A20: Lakenblekerstraat 21-B2, Алсмер | C20: 149.3 | E20: 221 м², 2025
A21: Zuid-Afrikaweg 3-N, Алсмер | C21: 134.2 | E21: 161 м², 2022
A22: Boeingavenue 303-A, Схипхол-Рейк | C22: 117 | E22: 200 м², 2020
A23: Boeingavenue 307-N — наша оценка | C23: 150 | E23: 193 м², средняя по двум этажам

Sheet Сценарии
A1: Сценарии и цена покупки
A2: Рассчитано той же моделью; активный сценарий переключается на листе «Допущения»
A4: Показатель | B4: Пессимистичный | C4: Базовый | D4: Оптимистичный | E4: Поздняя продажа
A5: Аренда в год | B5: 26055 | C5: 28950 | D5: 31845 | E5: 28950
A6: Доходность для инвестора | B6: 0.08 | C6: 0.0725 | D6: 0.0675 | E6: 0.0725
A7: Месяц въезда арендатора | B7: 5 | C7: 3 | D7: 2 | E7: 3
A8: Месяц продажи | B8: 10 | C8: 7 | D8: 6 | E8: 12
A9: Цена продажи | B9: 325687.5 | C9: 399310.34 | D9: 471777.78 | E9: 361694.15
A10: Все затраты | B10: 364105.68 | C10: 364663.71 | D10: 365722.22 | E10: 365360.18
A11: Прибыль до налога | B11: -31904.427 | C11: 41884.132 | D11: 114016.81 | E11: 15633.976
A12: Заработок на € 100 затрат | B12: -8.7624086 | C12: 11.485687 | D12: 31.175794 | E12: 4.2790586
A13: Прибыль после налога | B13: -31904.427 | C13: 33926.147 | D13: 92353.613 | E13: 12663.521
A14: Вложено своих денег на пике | B14: 391081.58 | C14: 391081.58 | D14: 391081.58 | E14: 391081.58
A15: Прибыль на свои деньги после налога | B15: -0.081579978 | C15: 0.086749539 | D15: 0.23614922 | E15: 0.032380764
A16: В пересчёте на год после налога (IRR) | B16: -0.10574595 | C16: 0.1662026 | D16: 0.57216331 | E16: 0.035684779
A19: Цена покупки и прибыль (базовые допущения)
A20: Цена покупки | B20: К цене продавца | C20: € за м² | D20: Прибыль, 7 месяцев | E20: На € 100 затрат, 7 месяцев | F20: В год, 7 месяцев | G20: Прибыль, 12 месяцев | H20: На € 100 затрат, 12 месяцев | I20: В год, 12 месяцев
A21: 360000 | B21: 0 | C21: 1865.285 | D21: -18925.868 | E21: -4.4481873 | F21: -0.075040271 | G21: -45326.024 | H21: -10.631921 | I21: -0.10864106
A22: 341326.23 | B22: -0.051871589 | C22: 1768.5297 | D22: 0 | E22: 0 | F22: 0 | G22: -26353.472 | H22: -6.4695288 | I22: -0.06624253
A23: 340000 | B23: -0.055555556 | C23: 1761.658 | D23: 1344.1322 | E23: 0.33171764 | F23: 0.0057073585 | G23: -25006.024 | H23: -6.1591165 | I23: -0.063073825
A24: 325000 | B24: -0.097222222 | C24: 1683.9378 | D24: 16546.632 | E24: 4.242713 | F24: 0.074168295 | G24: -9766.024 | H24: -2.4992373 | I24: -0.02564067
A25: 304859.63 | B25: -0.15316769 | C25: 1579.5836 | D25: 36958.895 | E25: 10 | F25: 0.17889696 | G25: 10696.59 | H25: 2.8886471 | I25: 0.02971698
A26: 300000 | B26: -0.16666667 | C26: 1554.4041 | D26: 41884.132 | E26: 11.485687 | F26: 0.20669116 | G26: 15633.976 | H26: 4.2790586 | I26: 0.044052393

Sheet Чувствительность
A1: Что будет, если расчёт не сойдётся
A2: Покупка за € 300.000, продажа на 7-м месяце; меняется одно допущение
A4: Если инвестор захочет другую доходность
A5: Инвестор хочет получать в год | B5: Значит, заплатит | C5: Наша прибыль
A6: 0.065 | B6: 445384.62 | C6: 87382.474
A7: 0.0675 | B7: 428888.89 | C7: 71092.944
A8: 0.07 | B8: 413571.43 | C8: 55966.952
A9: 0.0725 | B9: 399310.34 | C9: 41884.132
A10: 0.075 | B10: 386000 | C10: 28740.167
A11: 0.0775 | B11: 373548.39 | C11: 16444.199
A12: 0.08 | B12: 361875 | C12: 4916.7292
A14: Если аренда окажется другой
A15: Аренда к нашей оценке | B15: Аренда в год | C15: Инвестор заплатит | D15: Наша прибыль
A16: -0.15 | B16: 24607.5 | C16: 339413.79 | D16: -17697.963
A17: -0.1 | B17: 26055 | C17: 359379.31 | D17: 2162.7356
A18: -0.05 | B18: 27502.5 | C18: 379344.83 | D18: 22023.434
A19: 0 | B19: 28950 | C19: 399310.34 | D19: 41884.132
A20: 0.05 | B20: 30397.5 | C20: 419275.86 | D20: 61744.83
A21: 0.1 | B21: 31845 | C21: 439241.38 | D21: 81605.529
A22: 0.15 | B22: 33292.5 | C22: 459206.9 | D22: 101466.23
A24: Месяц въезда арендатора (строки) и месяц продажи (столбцы): прибыль до налога
A25: Въезд \ продажа | B25: 6 | C25: 7 | D25: 8 | E25: 10 | F25: 12
A26: 2 | B26: 42165.716 | C26: 44344.882 | D26: 9378.0593 | E26: 13736.393 | F26: 18094.726
A27: 3 | B27: 39704.966 | C27: 41884.132 | D27: 44063.299 | E27: 11275.643 | F27: 15633.976
A28: 5 | B28: 34783.466 | C28: 36962.632 | D28: 39141.799 | E28: 43500.132 | F28: 10712.476
A29: 7 | D29: 34220.299 | E29: 38578.632 | F29: 42936.966
A30: Продажа позже 6 месяцев после начала аренды: инвестор платит налог 10,4 % — ячейки: въезд 2 / продажа 8, въезд 2 / продажа 10, въезд 2 / продажа 12, въезд 3 / продажа 10, въезд 3 / продажа 12, въезд 5 / продажа 12
A32: Цена покупки (строки) и доходность для инвестора (столбцы): прибыль до налога
A33: Цена \ доходность | B33: 0.065 | C33: 0.0675 | D33: 0.07 | E33: 0.0725 | F33: 0.075 | G33: 0.0775 | H33: 0.08
A34: 290000 | B34: 97517.474 | C34: 81227.944 | D34: 66101.952 | E34: 52019.132 | F34: 38875.167 | G34: 26579.199 | H34: 15051.729
A35: 300000 | B35: 87382.474 | C35: 71092.944 | D35: 55966.952 | E35: 41884.132 | F35: 28740.167 | G35: 16444.199 | H35: 4916.7292
A36: 305000 | B36: 82314.974 | C36: 66025.444 | D36: 50899.452 | E36: 36816.632 | F36: 23672.667 | G36: 11376.699 | H36: -150.77083
A37: 325000 | B37: 62044.974 | C37: 45755.444 | D37: 30629.452 | E37: 16546.632 | F37: 3402.6667 | G37: -8893.3011 | H37: -20420.771
A38: 340000 | B38: 46842.474 | C38: 30552.944 | D38: 15426.952 | E38: 1344.1322 | F38: -11799.833 | G38: -24095.801 | H38: -35623.271
A39: 360000 | B39: 26572.474 | C39: 10282.944 | D39: -4843.0476 | E39: -18925.868 | F39: -32069.833 | G39: -44365.801 | H39: -55893.271
A40: 395000 | B40: -8900.0256 | C40: -25189.556 | D40: -40315.548 | E40: -54398.368 | F40: -67542.333 | G40: -79838.301 | H40: -91365.771
A43: Аренда к оценке (строки) и доходность для инвестора (столбцы): прибыль до налога
A44: Аренда \ доходность | B44: 0.065 | C44: 0.0675 | D44: 0.07 | E44: 0.0725 | F44: 0.075 | G44: 0.0775 | H44: 0.08
A45: 0.85 | B45: 20975.628 | C45: 7129.5278 | D45: -5727.5655 | E45: -17697.963 | F45: -28870.333 | G45: -39321.906 | H45: -49120.255
A46: 0.9 | B46: 43111.244 | C46: 28450.667 | D46: 14837.274 | E46: 2162.7356 | F46: -9666.8333 | G46: -20733.204 | H46: -31107.927
...

Sheet План Б
A1: План Б: если быстро продать не получается
A2: Формулы от листов «Допущения», «Аренда» и «Сводка»
A4: Держать сданным
A5: Расходы владельца, % аренды | B5: 0.125 | C5: налог OZB, страховка, ремонт, управление
A6: Чистый доход в год | B6: =rent_eff*(1-hold_opex)
A7: Вложено всего | B7: =acq_total+capex_total+rent_eff*letting_fee+marketing | C7: НДС к этому моменту возвращён
A8: Чистая доходность на вложенное | B8: =hold_noi/hold_invested
A9: Продать без арендатора по цене покупки
A10: Год содержания и простоя | B10: =buy_price*holding_pct+hold_fixed+void_m2*area_m2
A11: Все затраты | B11: =acq_total+capex_total+vac_carry+buy_price*sale_fee+sale_fixed
A12: Результат | B12: =buy_price-vac_cost | C12: крайний вариант: прибыль уходит на отделку и расходы

Sheet Конкуренты
A1: Сопоставимые объекты
A2: funda in business, выгрузка через Scrapling 20.10.2026
A4: Сданные помещения на продаже у Схипхола
A5: Объект | B5: м² | C5: Цена | D5: Аренда в год | E5: Доходность
A6: Tokyostraat 19-G, Лейнден | B6: 148 | C6: 325000 | D6: 22585 | E6: 0.0695
A7: F.A. Wentstraat 2-A, Алсмер | B7: 381 | C7: 495000 | D7: 28818 | E7: 0.0582
A8: Boeingavenue 305-F, ставка продавца | B8: 200 | C8: 425000 | D8: 33000 | E8: 0.0776
A10: Пустые юниты на продаже рядом
A11: Объект | B11: м² | C11: Цена | D11: € за м² | E11: Год
A12: Boeingavenue 307-N, наш юнит | B12: 193 | C12: 360000 | D12: 1865 | E12: 2025
A13: Boeingavenue 303-N | B13: 125 | C13: 335000 | D13: 2680 | E13: 2025
A14: Boeingavenue 303-E, с отделкой | B14: 108 | C14: 305000 | D14: 2824 | E14: 2026
A15: Boeingavenue 305-E | B15: 200 | C15: 400000 | D15: 2000 | E15: 2020
A16: Boeingavenue 305-F | B16: 200 | C16: 425000 | D16: 2125 | E16: 2020
A17: Boeingavenue 309-F | B17: 200 | C17: 585000 | D17: 2925 | E17: 2020
A18: Visserstraat 14-B, Алсмер | B18: 177 | C18: 335000 | D18: 1893 | E18: 2026
A19: Lakenblekerstraat 21-A5, Алсмер | B19: 212 | C19: 430000 | D19: 2028 | E19: 2025
A20: Burgemeester Hoffscholteweg 1-02, Алсмер | B20: 228 | C20: 380000 | D20: 1667 | E20: 2022
A22: Склады и юниты на продаже в наших зонах: одна модель для всех
A23: Объект | B23: Здание | C23: Цена продавца | D23: Аренда в год, оценка | E23: Доходность для инвестора | F23: Итог по цене продавца | G23: Цена «в ноль» к цене продавца | H23: Цена для € 10 на € 100 затрат
A24: Sijsjesbergweg 4-C2, Амстердам | B24: новый, с НДС | C24: 380000 | D24: 32130 | E24: 0.07 | F24: 24303.083 | G24: 0.063103584 | H24: -0.047138412
A25: Boeingavenue 307-N, Схипхол-Рейк | B25: новый, с НДС | C25: 360000 | D25: 28950 | E25: 0.0725 | F25: -18925.868 | G25: -0.051871589 | H25: -0.15316769
A26: Van Riemsdijkweg 17, Роттердам | B26: 1957, налог 10,4 % | C26: 895000 | D26: 71700 | E26: 0.075 | F26: -83989.4 | G26: -0.083788308 | H26: -0.17319872
A27: Visserstraat 14-B, Алсмер | B27: новый, с НДС | C27: 335000 | D27: 23895 | E27: 0.0725 | F27: -59738.454 | G27: -0.17594844 | H27: -0.26579654
A28: Televisieweg 141, Алмере | B28: 1999, налог 10,4 % | C28: 299500 | D28: 21660 | E28: 0.0725 | F28: -58410.462 | G28: -0.17413088 | H28: -0.25754469
A29: Palmpolstraat 99-G26, Алмере | B29: новый, с НДС | C29: 279900 | D29: 19360 | E29: 0.0725 | F29: -62709.432 | G29: -0.22105799 | H29: -0.30818426
A30: Willem Brocadesdreef 180, Хофддорп | B30: 2008, налог 10,4 % | C30: 285000 | D30: 19665 | E30: 0.0725 | F30: -69639.338 | G30: -0.21816835 | H30: -0.29775229
A31: Theemsweg 62, Амстердам | B31: 2002, налог 10,4 % | C31: 410000 | D31: 26780 | E31: 0.07 | F31: -100485.58 | G31: -0.21882748 | H31: -0.29677525
A32: Новые помещения — схема с НДС и продажа на 7-м месяце; старые здания — налог 10,4 % и продажа через 12 месяцев. У Van Riemsdijkweg 17 учтена плата за эрфпахт € 8.666 в год.

Sheet Источники
A1: Источники и правила
A4: Объект | B4: https://www.fundainbusiness.nl/bedrijfshal/schiphol-rijk/object-43009847-boeingavenue-307-n/ — € 360.000 vrij op naam без НДС, налога на передачу нет; сдан в 2025 году; разрешение — промышленность с подчинённым офисом
A5: Налог на передачу | B5: Wet op belastingen van rechtsverkeer, ст. 14: 10,4 % для нежилой недвижимости
A6: Схема с НДС | B6: Там же, ст. 15, часть 1, пункт a: покупка нового здания, облагаемая НДС, освобождена от налога на передачу; если помещение уже использовалось как рабочий актив, освобождение сохраняется при покупке в течение 6 месяцев после начала использования — для сданного помещения это начало аренды
A7: НДС | B7: 21 %; продажа здания обязательно с НДС до 2 лет после начала использования; аренда с НДС — только арендатору с правом на вычет
A8: Налог на прибыль | B8: VPB 2026: 19 % до € 200.000, 25,8 % сверх (KVK)
