Workbook

Sheet Сводка
A1: Oude Binnenweg 55, Rotterdam — мы в рынке или нет?
A2: Проверка запрашиваемой ставки €70 000/год за 161,10 м² против 23 конкурентных предложений в центре Роттердама. Четыре независимых теста. Все расчёты — формулы; входные допущения на листе «Методика».
A4: НАШ ОБЪЕКТ
A5: Адрес | B5: Oude Binnenweg 55, 3012 JA Rotterdam | C5: Здание 1953 г., арх. Teunis Wilschut, построено для сети De Gruyter. Витрина ок. 8 м. Предыдущий известный арендатор — Scotch & Soda (2016).
A6: Ставка, €/год | B6: =Методика!$B$10 -> 70000 | C6: Запрашиваемая, без НДС. Задана клиентом.
A7: Общая площадь, м² | B7: =Методика!$B$13 -> 161.1 | C7: 115,0 м² 1-й этаж + 46,1 м² подвал. Доля подвала — 29% площади.
A8: €/м²/год (общая площадь) | B8: =Все_объекты!N22 -> 434.51273 | C8: Ставка ÷ 161,10 м².
A9: €/м²/мес (общая площадь) | B9: =Все_объекты!O22 -> 36.209394 | C9: В задании указано €35,79 — это соответствует площади 162,98 м². Корректная величина при 161,10 м² — см. значение слева.
A10: €/м²/год, приведённые к 1-му этажу | B10: =Все_объекты!P22 -> 553.25035 | C10: Ставка ÷ приведённую площадь (1-й этаж + подвал×0,25). Основной показатель для сравнения.
A11: Проходимость | B11: =Методика!$B$19&" чел./нед." -> 86000 чел./нед. | C11: Измерено (Ooms). Для сравнения: Lijnbaan 213 000, Hoogstraat 260 000. Мы — 40% от потока Lijnbaan.
A13: ТЕСТ 1 · ПРОТИВ ВСЕЙ ВЫБОРКИ (n = 20 сопоставимых из 23)
A14: Медиана рынка, €/м²/год привед. | B14: =MEDIAN(Все_объекты!Z$4:Z$27) -> 375.21583
A15: Наше отклонение | B15: =Все_объекты!P22/MEDIAN(Все_объекты!Z$4:Z$27)-1 -> 0.4744856 | C15: ВЫШЕ медианы. Но выборка содержит крупноформатные лоты 400–834 м², где €/м² механически ниже, и слабые локации с индексом проходимости 40–45. Сравнение «в лоб» некорректно — см. тест 2.
A17: ТЕСТ 2 · ПРОТИВ СОПОСТАВИМЫХ ПО РАЗМЕРУ (100–210 м², n = 9)
A18: Медиана, €/м²/год (общая) | B18: =MEDIAN(Все_объекты!AB$4:AB$27) -> 418.34862
A19: Наше отклонение по общей площади | B19: =Все_объекты!N22/MEDIAN(Все_объекты!AB$4:AB$27)-1 -> 0.038637873 | C19: Практически ровно на медиане сопоставимых по размеру объектов.
A20: Медиана, €/м²/год (привед.) | B20: =MEDIAN(Все_объекты!AA$4:AA$27) -> 418.34862
A21: Наше отклонение по привед. площади | B21: =Все_объекты!P22/MEDIAN(Все_объекты!AA$4:AA$27)-1 -> 0.32246245 | C21: Выше. Медиана здесь приходится на Van Oldenbarneveltstraat 97 — 109 м² чистого 1-го этажа без подвала за €418/м². Разрыв объясняется тем, что 4 из 9 объектов этой подвыборки стоят в локациях с проходимостью вдвое ниже нашей (Westblaak, Schiedamsedijk, Goudsesingel).
A23: ТЕСТ 3 · МОДЕЛЬ, УЧИТЫВАЮЩАЯ ОДНОВРЕМЕННО РАЗМЕР И ПРОХОДИМОСТЬ
A24: Регрессия по 20 сопоставимым объектам: ln(€/м² привед.) = a + b×ln(привед. площадь) + c×ln(индекс проходимости)
A25: a (константа) | B25: 6.7585 | C25: Коэффициенты рассчитаны методом наименьших квадратов по выборке из 20 объектов и внесены как константы.
A26: b (эластичность по площади) | B26: -0.4594 | C26: Отрицательная: каждое удвоение площади снижает ставку за метр примерно на 27%. Это и есть эффект масштаба, из-за которого лоты на Korte Hoogstraat выглядят «дёшево».
A27: c (эластичность по проходимости) | B27: 0.3862 | C27: Положительная: удвоение потока поднимает ставку за метр примерно на 31%.
A28: R² модели | B28: 0.422 | C28: Модель объясняет 42% разброса. Типичное отклонение факта от модели: −29% / +41%. Это ориентир, а не оценка.
A29: Расчётная справедливая ставка, €/м²/год привед. | B29: =EXP($B$25+$B$26*LN(Все_объекты!H22)+$B$27*LN(100)) -> 551.87338 | C29: При нашей приведённой площади и нашей проходимости (индекс 100).
A30: Расчётная справедливая аренда, €/год | B30: =B29*Все_объекты!H22 -> 69825.779
A31: Диапазон модели, €/год | B31: ="от "&TEXT($B$30*EXP(-0.34),"#,##0")&" € до "&TEXT($B$30*EXP(0.34),"#,##0")&" €" -> от 49,700 € до 98,102 € | C31: ±1 стандартное отклонение остатков.
A32: Факт €70 000 против модели | B32: =Все_объекты!L22/$B$30-1 -> 0.0024950836 | C32: Совпадение практически точное.
A34: ТЕСТ 4 · ПРОТИВ ПРАЙМ-СТАВКИ РОТТЕРДАМА (зонирование зоны A)
A35: Глубина 1-го этажа, м | B35: =Методика!$B$11/Методика!$B$14 -> 14.375 | C35: 115 м² ÷ 8 м витрины.
A36: Зона A (первые 10 м), м² | B36: =MIN($B$35,Методика!$B$15)*Методика!$B$14 -> 80 | C36: Вес 100%.
A37: Зона B (остаток), м² | B37: =MAX(0,$B$35-Методика!$B$15)*Методика!$B$14 -> 35 | C37: Вес 50%.
A38: Эквивалент зоны A, м² | B38: =$B$36+$B$37*Методика!$B$16+Методика!$B$12*Методика!$B$6 -> 109.025 | C38: Зона A + зона B×0,5 + подвал×0,25.
A39: Наша ставка зоны A, €/м²/год | B39: =Методика!$B$10/$B$38 -> 642.05457
A40: Прайм-ставка зоны A, Lijnbaan | B40: =Методика!$B$22 -> 1400 | C40: CBRE, 2025.
A41: Мы в % от прайма | B41: =$B$39/$B$40 -> 0.45861041
A42: Наша проходимость в % от Lijnbaan | B42: =Методика!$B$19/Методика!$B$20 -> 0.40375587 | C42: Ключевая сходимость: мы платим 46% прайм-ставки при 40% прайм-потока. Для улицы класса A2 удержание 35–50% прайма — нормальный рыночный уровень.
A44: ВЫВОД
A45: ДА, МЫ В РЫНКЕ — но у верхней границы справедливого диапазона, а не в середине.
A46: Три из четырёх тестов сходятся.
...

Sheet Методика
A1: Методика, допущения и оговорки
A2: Все входные допущения модели собраны в блоке ниже и подтягиваются формулами на остальные листы. Изменение жёлтой ячейки пересчитывает весь файл.
A4: 1. ВЕСА ПРИВЕДЕНИЯ ПЛОЩАДЕЙ (голландская практика зонирования торговых площадей)
A5: Вес 1-го этажа | B5: 1 | C5: База. Первый этаж — единственный уровень, генерирующий полноценный торговый оборот.
A6: Вес подвала (kelder / souterrain) | B6: 0.25 | C6: Рынок Нидерландов оценивает подвал в 20–25% от ставки 1-го этажа: это склад/подсобка, а не торговля. 25% — верхняя, т.е. консервативная для арендодателя граница.
A7: Вес прочих уровней (антресоль, 2-й этаж) | B7: 0.35 | C7: Антресоль/2-й этаж с доступом из зала — 25–50%. Принято 0,35.
A9: 2. ИСХОДНЫЕ ДАННЫЕ ПО НАШЕМУ ОБЪЕКТУ (Oude Binnenweg 55) — со слов клиента
A10: Арендная ставка, €/год | B10: 70000 | C10: Задана клиентом. Единственная известная величина — общая ставка за оба уровня; раздельных ставок по 1-му этажу и подвалу нет.
A11: Площадь 1-го этажа, м² | B11: 115 | C11: Задана клиентом.
A12: Площадь подвала, м² | B12: 46.1 | C12: Задана клиентом.
A13: Общая площадь, м² (расчёт) | B13: =B11+B12 -> 161.1 | C13: Проверка: 115 + 46,1 = 161,10 м² — сходится с данными клиента.
A14: Ширина витрины, м | B14: 8 | C14: Из экспозиции Ooms/iLocate по адресу Oude Binnenweg 55 («ca. 8 meter»). Ширина фасада здания по данным о постройке — 9 м.
A15: Глубина зоны A, м | B15: 10 | C15: Стандарт зонирования: первые 10 м глубины от витрины = зона A (100%), далее зона B (50%).
A16: Вес зоны B | B16: 0.5 | C16: Остаток глубины 1-го этажа за пределами первых 10 м.
A18: 3. ВНЕШНИЕ РЕПЕРЫ (для перекрёстной проверки)
A19: Проходимость Oude Binnenweg, чел./нед. | B19: 86000 | C19: Ooms Makelaars (бизнес-кейс по Oude Binnenweg 57A — соседнее с нами помещение), характеризует улицу как A-локацию.
A20: Проходимость Lijnbaan, чел./нед. | B20: 213000 | C20: RetailSonar, замер по данным смартфонов, период VI.2022 – V.2023. 7-е место в Нидерландах.
A21: Проходимость Hoogstraat, чел./нед. | B21: 260000 | C21: RetailSonar, там же. 3-е место в Нидерландах, самая посещаемая улица Роттердама.
A22: Прайм-ставка зоны A, Lijnbaan, €/м²/год | B22: 1400 | C22: CBRE, «The Resilience of Dutch Prime Shopping Streets», 2025. Верхний рыночный ориентир Роттердама.
A24: 4. КАК СЧИТАЛИСЬ ПОКАЗАТЕЛИ
A25: • «€/м²/год (общая)» = запрашиваемая годовая ставка ÷ общая площадь объекта. Самый простой, но и самый искажающий показатель: он неявно приравнивает подвал к торговому залу и игнорирует эффект масштаба.
A26: • «Приведённая площадь» = 1-й этаж×1,00 + подвал×0,25 + прочие уровни×0,35. «€/м²/год (привед.)» = ставка ÷ приведённая площадь. Это ставка, приведённая к эквиваленту 1-го этажа, — корректная база для сравнения объектов с разной долей подвала. У нас подвал даёт 29% общей площади, у Botersloot 52-A — 55%, у Meent 121 — 50%, у Karel Doormanstraat 320-322 и Van Oldenbarneveltstraat 97 — 0%. Без приведения эти объекты несопоставимы в принципе.
A27: • «Отклонение от нашей ставки» считается по €/м²/год приведённой, т.е. после устранения искажения от подвала.
A28: • Индекс проходимости: наш объект = 100. Для Oude Binnenweg, Lijnbaan и Hoogstraat индекс рассчитан из ИЗМЕРЕННЫХ данных (см. блок 3) и помечен «изм.». Для остальных улиц публичных замеров нет — индекс проставлен экспертно по классу локации, функции улицы и расстоянию до ядра, и помечен «оценка». Различие важно: измеренные значения можно защищать в переговорах, оценочные — нет.
A29: • Все ставки в таблице — ЗАПРАШИВАЕМЫЕ (asking) и БЕЗ НДС. Фактические сделки на голландском стрит-ритейле закрываются, как правило, на 5–15% ниже экспозиции, плюс стимулы (huurvrije periode, вклад в отделку), которые в объявлениях не раскрываются. Реальный рыночный уровень ниже расчётной медианы.
A30: • Сервисные расходы вынесены в отдельный столбец и НЕ включены в €/м². Они существенно различаются: от нуля до €37,50/м²/год (Westblaak 159, +13% к базовой ставке). При сравнении полной стоимости занятия помещения их надо приплюсовывать.
A32: 5. ОГОВОРКИ И ДЕФЕКТЫ ИСХОДНЫХ ДАННЫХ (обязательно к прочтению)
A33: Ставка €35,79/м²/мес из задания не сходится. | B33: €70 000 ÷ 161,10 м² ÷ 12 = €36,21/м²/мес. Указанные €35,79 соответствуют площади 162,98 м², а не 161,10 м². Расхождение 1,2% — во всех расчётах использована ставка €70 000/год как первичная величина, а не производная €/м²/мес.
A34: Площади нашего объекта расходятся с рыночной экспозицией. | B34: Клиент: 115 + 46,1 = 161,10 м². Экспозиция Ooms/iLocate по Oude Binnenweg 55: ок. 120 м² 1-й этаж + ок. 42 м² подвал = 162 м². Сделка 2016 г. со Scotch & Soda описывалась как ок. 127 м² + ок. 60 м² подвала. Три разных набора цифр по одному адресу — перед переговорами нужен обмер NEN 2580.
A35: Наш объект, судя по всему, СЕЙЧАС В ЭКСПОЗИЦИИ. | B35: На iLocate помещение по адресу Oude Binnenweg 55 предлагается в аренду через Ooms Makelaars, срок 10 + 2×5 лет, цена «на запрос». Если €70 000 — это asking, а не подписанный договор, то это верхняя граница переговоров, и фактическая ставка будет ниже. Вывод «мы в рынке» относится к запрашиваемому уровню.
A36: Witte de Withstraat 2 и Schiedamse Vest 89 — вероятно, один и тот же объект. | B36: Совпадают площадь (401 м²), ставка (€125 000), сервис (€20/м²/год) и год постройки (1928); разбивка «1-й этаж/подвал» зеркально перевёрнута (215/186 против 186/215); угловое здание на пересечении этих улиц. Брокеры разные (Parc Makelaars и KroesePaternotte). Во избежание двойного счёта в выборке учтён один раз.
A37: Два объекта исключены как несопоставимые. | B37: Karel Doormanstraat 451-A — сервисный кабинет 18 м² по модели all-in (€875/мес включая интернет, электричество и кухню, возможна почасовая/подневная аренда): это продажа услуги, а не аренда помещения. Schiedamsedijk 3 — €990/мес за ОДНУ студию от 12 м² в салоне Gallery Salon Studios, а не за объект 99 м²; прямое деление дало бы фиктивные €120/м²/год.
A38: Разбивка Lijnbaan 58 — оценочная. | B38: Объявление даёт 395 м² на двух уровнях без разбивки по этажам. При витрине 8 м принято ~200 м² 1-й этаж + ~195 м² второй. Приведённая ставка по этому объекту чувствительна к допущению и в переговорах на неё опираться не следует.
A39: Расхождение внутри объявления Schiedamsedijk 8-A. | B39: Заявлено 200 м² всего, но по уровням дано 80 + 90 = 170 м². 30 м² не детализированы. Расчёт приведённой площади сделан по детализированным 170 м².
A40: Разбивка Oude Binnenweg 150-A — приблизительная. | B40: Объявление: 140 м² всего, 120 м² торговых, 3 уровня, при этом сам объект помечен как расположенный на уровне −1. Принято 120 м² торговых + 20 м² прочих.
A41: Хорека ≠ ритейл. | B41: Oude Binnenweg 150-A и 117-119 — объекты общепита. Это лучшие по локации аналоги (та же улица), но общепит обычно платит премию к ритейлу за ту же площадь, а у 117-119 сверх аренды берут €50 000 гудвилла. Сравнение с ними завышает «нормальный» уровень для ритейла.
A42: Модель регрессии объясняет 42% разброса. | B42: R² = 0,42 при n = 20 — это ориентир, а не оценка. Типичный разброс факта вокруг модели: −29% / +41%. Вывод «в рынке» опирается на СОВПАДЕНИЕ трёх независимых тестов, а не на один этот показатель.
A44: 6. ИСТОЧНИКИ
A45: • funda in business — 23 объявления, предоставленные клиентом (выгрузка: август 2026). Ссылки в столбце X листа «Все_объекты».
A46: • Ooms Makelaars — бизнес-кейс по Oude Binnenweg 57A: проходимость улицы ок. 86 000 чел./нед., классификация A-локация. https://ooms.com/actueel/bedrijfscase-verhuur-oude-binnenweg-57a
...

Sheet Все_объекты
A1: Роттердам · стрит-ритейл · сравнительный анализ арендных ставок и характеристик
A2: Объект оценки: Oude Binnenweg 55, Rotterdam · 161,10 м² (115 м² 1-й этаж + 46,1 м² подвал) · €70 000/год | База сравнения: 23 объявления funda in business, предоставленные клиентом | Сортировка — по возрастанию приведённой ставки €/м²/год | Столбцы «Привед. пл.», «€/м²…», «Откл.» — расчётные формулы | Все ставки — ЗАПРАШИВАЕМЫЕ, без НДС
A3: № | B3: Адрес | C3: Тип объекта | D3: Общая пл., м² | E3: 1-й этаж, м² | F3: Подвал, м² | G3: Прочие уровни, м² | H3: Привед. пл., м² | I3: Витрина, м | J3: Год постр. | K3: Состояние / отделка | L3: Ставка, €/год | M3: Сервис. расх., €/год | N3: €/м²/год (общая) | O3: €/м²/мес (общая) | P3: €/м²/год (привед.) | Q3: Откл. от нашей ставки | R3: Индекс проход. (наш=100) | S3: Проходимость vs наш | T3: Класс локации | U3: Статус | V3: В выборке | W3: Примечание / дефекты данных | X3: Ссылка
A4: 1 | B4: Schiedamsedijk 3, 3011 EB | C4: Салон-студии (аренда рабочего места) | D4: 99 | H4: =IF(SUM(E4:G4)=0,"",E4*Методика!$B$5+F4*Методика!$B$6+G4*Методика!$B$7) | I4: 3 | J4: 1981 | K4: Оборудовано: кухня/бэк-бар, проф. свет, мойка | L4: 11880 | M4: не раскрыто | N4: =IFERROR(L4/D4,"") -> 120 | O4: =IFERROR(N4/12,"") -> 10 | P4: =IFERROR(L4/H4,"") | Q4: =IFERROR(P4/$P$22-1,"") | R4: 40 | S4: Хуже | T4: B2 | U4: Свободно, per direct | V4: 0 | W4: НЕ СОПОСТАВИМ: €990/мес — ставка ЗА ОДНУ СТУДИЮ от 12 м² в рамках Gallery Salon Studios (модель членства), а не за объект 99 м². Приведение к €/м² объекта дало бы искусственно заниженные €120/м²/год. Исключён. | X4: https://www.fundainbusiness.nl/en/winkel/rotterdam/object-89674389-schiedamsedijk-3/ | Y4: =IF($V4=1,N4,"") | Z4: =IF($V4=1,P4,"") | AA4: =IF($V4=1,IF(AND($D4>=100,$D4<=210),P4,""),"") | AB4: =IF($V4=1,IF(AND($D4>=100,$D4<=210),N4,""),"")
A5: 2 | B5: Schouwburgplein 9, 3012 CL | C5: Винкель + шоурум | D5: 356 | E5: 356 | F5: 0 | G5: 0 | H5: =IF(SUM(E5:G5)=0,"",E5*Методика!$B$5+F5*Методика!$B$6+G5*Методика!$B$7) -> 356 | J5: н/д | K5: Casco | L5: 74760 | M5: не раскрыто | N5: =IFERROR(L5/D5,"") -> 210 | O5: =IFERROR(N5/12,"") -> 17.5 | P5: =IFERROR(L5/H5,"") -> 210 | Q5: =IFERROR(P5/$P$22-1,"") -> -0.620425 | R5: 105 | S5: Сопоставимо / чуть лучше | T5: A2 | U5: Свободно (в согласовании) | V5: 1 | W5: 500 м до Centraal Station, у Lijnbaan/Koopgoot. Высокий транзит, но площадь — событийно-досуговая, retail-задержка ниже витринной улицы. | X5: https://www.fundainbusiness.nl/en/winkel/rotterdam/object-89056875-schouwburgplein-9/ | Y5: =IF($V5=1,N5,"") -> 210 | Z5: =IF($V5=1,P5,"") -> 210 | AA5: =IF($V5=1,IF(AND($D5>=100,$D5<=210),P5,""),"") | AB5: =IF($V5=1,IF(AND($D5>=100,$D5<=210),N5,""),"")
A6: 3 | B6: Groenendaal 245, 3011 ZW | C6: Винкель + шоурум | D6: 468 | E6: 468 | F6: 0 | G6: 0 | H6: =IF(SUM(E6:G6)=0,"",E6*Методика!$B$5+F6*Методика!$B$6+G6*Методика!$B$7) -> 468 | I6: 40 | J6: н/д | K6: Casco (без отделки) | L6: 105000 | M6: 600 | N6: =IFERROR(L6/D6,"") -> 224.35897 | O6: =IFERROR(N6/12,"") -> 18.696581 | P6: =IFERROR(L6/H6,"") -> 224.35897 | Q6: =IFERROR(P6/$P$22-1,"") -> -0.59447115 | R6: 45 | S6: Хуже | T6: B1 | U6: Свободно (в согласовании) | V6: 1 | W6: Первый этаж жилого комплекса у Oostplein/Blaak. Соседи: Albert Heijn, Trekpleister. Зонирование Centrum-6 — хорека ЗАПРЕЩЕНА. | X6: https://www.fundainbusiness.nl/en/winkel/rotterdam/object-80838997-groenendaal-245/ | Y6: =IF($V6=1,N6,"") -> 224.35897 | Z6: =IF($V6=1,P6,"") -> 224.35897 | AA6: =IF($V6=1,IF(AND($D6>=100,$D6<=210),P6,""),"") | AB6: =IF($V6=1,IF(AND($D6>=100,$D6<=210),N6,""),"")
A7: 4 | B7: Goudsesingel 247, 3031 EL | C7: Винкель (verkoopruimte) | D7: 136 | E7: 100 | F7: 36 | G7: 0 | H7: =IF(SUM(E7:G7)=0,"",E7*Методика!$B$5+F7*Методика!$B$6+G7*Методика!$B$7) -> 109 | I7: 6.9 | J7: 1956 | K7: Тек. состояние, свободно и пусто | L7: 30000 | M7: не раскрыто | N7: =IFERROR(L7/D7,"") -> 220.58824 | O7: =IFERROR(N7/12,"") -> 18.382353 | P7: =IFERROR(L7/H7,"") -> 275.22936 | Q7: =IFERROR(P7/$P$22-1,"") -> -0.50252294 | R7: 45 | S7: Хуже | T7: B1 | U7: Свободно с 01.01.2027 | V7: 1 | W7: Энергометка A+. Взнос BIZ. Договор 5+5. Доступен только с 2027 г. | X7: https://www.fundainbusiness.nl/en/winkel/rotterdam/object-44493275-goudsesingel-247/ | Y7: =IF($V7=1,N7,"") -> 220.58824 | Z7: =IF($V7=1,P7,"") -> 275.22936 | AA7: =IF($V7=1,IF(AND($D7>=100,$D7<=210),P7,""),"") -> 275.22936 | AB7: =IF($V7=1,IF(AND($D7>=100,$D7<=210),N7,""),"") -> 220.58824
A8: 5 | B8: Westblaak 159, 3012 KJ | C8: Винкель + шоурум | D8: 134 | E8: 134 | F8: 0 | G8: 0 | H8: =IF(SUM(E8:G8)=0,"",E8*Методика!$B$5+F8*Методика!$B$6+G8*Методика!$B$7) -> 134 | J8: 1978 | K8: Casco | L8: 37500 | M8: 5025 | N8: =IFERROR(L8/D8,"") -> 279.85075 | O8: =IFERROR(N8/12,"") -> 23.320896 | P8: =IFERROR(L8/H8,"") -> 279.85075 | Q8: =IFERROR(P8/$P$22-1,"") -> -0.49416978 | R8: 40 | S8: Хуже | T8: B2 | U8: Свободно, per direct | V8: 1 | W8: Транспортная магистраль Westblaak — автомобильный, а не пешеходный поток. Сервисные расходы €37,50/м²/год — самые высокие в выборке (+13% к базовой ставке). | X8: https://www.fundainbusiness.nl/en/winkel/rotterdam/object-89729432-westblaak-159/ | Y8: =IF($V8=1,N8,"") -> 279.85075 | Z8: =IF($V8=1,P8,"") -> 279.85075 | AA8: =IF($V8=1,IF(AND($D8>=100,$D8<=210),P8,""),"") -> 279.85075 | AB8: =IF($V8=1,IF(AND($D8>=100,$D8<=210),N8,""),"") -> 279.85075
A9: 6 | B9: Korte Hoogstraat 9-A, 3011 GJ | C9: Винкель + шоурум, 2 уровня | D9: 834 | E9: 476 | F9: 358 | G9: 0 | H9: =IF(SUM(E9:G9)=0,"",E9*Методика!$B$5+F9*Методика!$B$6+G9*Методика!$B$7) -> 565.5 | I9: 10 | J9: 1954 | K9: Casco | L9: 171000 | M9: не раскрыто | N9: =IFERROR(L9/D9,"") -> 205.03597 | O9: =IFERROR(N9/12,"") -> 17.086331 | P9: =IFERROR(L9/H9,"") -> 302.38727 | Q9: =IFERROR(P9/$P$22-1,"") -> -0.45343501 | R9: 300 | S9: СИЛЬНО ЛУЧШЕ (изм.) | T9: A1 (прайм) | U9: Свободно (в согласовании) | V9: 1 | W9: У входа в De Koopgoot. Соседи: HEMA, Bristol, Dille & Kamille. Крупный формат — эффект масштаба сильно занижает €/м². Первая заявленная ставка была €13 950/мес, текущая €14 250/мес. | X9: https://www.fundainbusiness.nl/en/winkel/rotterdam/object-89259857-korte-hoogstraat-9-a/ | Y9: =IF($V9=1,N9,"") -> 205.03597 | Z9: =IF($V9=1,P9,"") -> 302.38727 | AA9: =IF($V9=1,IF(AND($D9>=100,$D9<=210),P9,""),"") | AB9: =IF($V9=1,IF(AND($D9>=100,$D9<=210),N9,""),"")
A10: 7 | B10: Karel Doormanstraat 257-259, 3012 GH | C10: Винкель | D10: 491 | E10: 491 | F10: 0 | G10: 0 | H10: =IF(SUM(E10:G10)=0,"",E10*Методика!$B$5+F10*Методика!$B$6+G10*Методика!$B$7) -> 491 | I10: 37 | J10: 1987 | K10: Casco, свободно и чисто | L10: 150000 | M10: не раскрыто | N10: =IFERROR(L10/D10,"") -> 305.49898 | O10: =IFERROR(N10/12,"") -> 25.458248 | P10: =IFERROR(L10/H10,"") -> 305.49898 | Q10: =IFERROR(P10/$P$22-1,"") -> -0.44781059 | R10: 80 | S10: Немного хуже | T10: A2 / B1 | U10: Свободно (в согласовании) | V10: 1 | W10: ЕДИНСТВЕННЫЙ ОБЪЕКТ С ЯВНОЙ УДЕЛЬНОЙ СТАВКОЙ: €305/м²/год (согласуется с €12 500/мес). Энергометки A++/A+. Делится на блоки 309 и 182 м². | X10: https://www.fundainbusiness.nl/en/winkel/rotterdam/object-43039916-karel-doormanstraat-257-259/ | Y10: =IF($V10=1,N10,"") -> 305.49898 | Z10: =IF($V10=1,P10,"") -> 305.49898 | AA10: =IF($V10=1,IF(AND($D10>=100,$D10<=210),P10,""),"") | AB10: =IF($V10=1,IF(AND($D10>=100,$D10<=210),N10,""),"")
A11: 8 | B11: Schiedamsedijk 8-A, 3011 EC | C11: Мультифункц. винкель + склад/гараж | D11: 200 | E11: 80 | F11: 90 | G11: 0 | H11: =IF(SUM(E11:G11)=0,"",E11*Методика!$B$5+F11*Методика!$B$6+G11*Методика!$B$7) -> 102.5 | J11: 1950 | K11: Не указано | L11: 36000 | M11: 0 | N11: =IFERROR(L11/D11,"") -> 180 | O11: =IFERROR(N11/12,"") -> 15 | P11: =IFERROR(L11/H11,"") -> 351.21951 | Q11: =IFERROR(P11/$P$22-1,"") -> -0.36517073 | R11: 40 | S11: Хуже | T11: B2 | U11: Свободно (в согласовании) | V11: 1 | W11: РАСХОЖДЕНИЕ В ИСТОЧНИКЕ: заявлено 200 м² всего, но по уровням дано 80 + 90 = 170 м². 30 м² не детализированы. Нижний уровень — склад/гараж (Brandersplaats), не торговый. | X11: https://www.fundainbusiness.nl/en/winkel/rotterdam/object-43213501-schiedamsedijk-8-a/ | Y11: =IF($V11=1,N11,"") -> 180 | Z11: =IF($V11=1,P11,"") -> 351.21951 | AA11: =IF($V11=1,IF(AND($D11>=100,$D11<=210),P11,""),"") -> 351.21951 | AB11: =IF($V11=1,IF(AND($D11>=100,$D11<=210),N11,""),"") -> 180
A12: 9 | B12: Goudsesingel 227-229, 3031 EK | C12: Винкель + шоурум | D12: 335 | E12: 265 | F12: 70 | G12: 0 | H12: =IF(SUM(E12:G12)=0,"",E12*Методика!$B$5+F12*Методика!$B$6+G12*Методика!$B$7) -> 282.5 | J12: 1954 | K12: В состоянии сдачи тек. арендатором | L12: 99500 | M12: не раскрыто | N12: =IFERROR(L12/D12,"") -> 297.01493 | O12: =IFERROR(N12/12,"") -> 24.751244 | P12: =IFERROR(L12/H12,"") -> 352.21239 | Q12: =IFERROR(P12/$P$22-1,"") -> -0.36337611 | R12: 45 | S12: Хуже | T12: B1 | U12: Свободно (в согласовании) | V12: 1 | W12: Большие витрины, высокие потолки. Метро Oostplein. Договор 5+5. | X12: https://www.fundainbusiness.nl/en/winkel/rotterdam/object-89678041-goudsesingel-227-229/ | Y12: =IF($V12=1,N12,"") -> 297.01493 | Z12: =IF($V12=1,P12,"") -> 352.21239 | AA12: =IF($V12=1,IF(AND($D12>=100,$D12<=210),P12,""),"") | AB12: =IF($V12=1,IF(AND($D12>=100,$D12<=210),N12,""),"")
A13: 10 | B13: Korte Hoogstraat 19, 3011 GK | C13: Винкель + шоурум, 3 уровня | D13: 465 | E13: 235 | F13: 165 | G13: 65 | H13: =IF(SUM(E13:G13)=0,"",E13*Методика!$B$5+F13*Методика!$B$6+G13*Методика!$B$7) -> 299 | J13: 1953 | K13: Casco / тек. состояние | L13: 107400 | M13: не раскрыто | N13: =IFERROR(L13/D13,"") -> 230.96774 | O13: =IFERROR(N13/12,"") -> 19.247312 | P13: =IFERROR(L13/H13,"") -> 359.19732 | Q13: =IFERROR(P13/$P$22-1,"") -> -0.35075084 | R13: 300 | S13: СИЛЬНО ЛУЧШЕ (изм.) | T13: A1 (прайм) | U13: Свободно (в согласовании) | V13: 1 | W13: Прочие уровни = антресоль ок. 65 м². Договор 5 + 2×5. Крупный формат. | X13: https://www.fundainbusiness.nl/en/winkel/rotterdam/object-43523125-korte-hoogstraat-19/ | Y13: =IF($V13=1,N13,"") -> 230.96774 | Z13: =IF($V13=1,P13,"") -> 359.19732 | AA13: =IF($V13=1,IF(AND($D13>=100,$D13<=210),P13,""),"") | AB13: =IF($V13=1,IF(AND($D13>=100,$D13<=210),N13,""),"")
A14: 11 | B14: Mariniersweg 82-A, 3011 NT | C14: Винкель + шоурум | D14: 182.51 | E14: 152.76 | F14: 29.75 | G14: 0 | H14: =IF(SUM(E14:G14)=0,"",E14*Методика!$B$5+F14*Методика!$B$6+G14*Методика!$B$7) -> 160.1975 | J14: 1956 | K14: Casco | L14: 59900 | M14: не раскрыто | N14: =IFERROR(L14/D14,"") -> 328.20119 | O14: =IFERROR(N14/12,"") -> 27.3501 | P14: =IFERROR(L14/H14,"") -> 373.91345 | Q14: =IFERROR(P14/$P$22-1,"") -> -0.32415144 | R14: 60 | S14: Хуже | T14: B1 | U14: Свободно (в согласовании) | V14: 1 | W14: Энергометка A+++. Рядом Meent, Hoogstraat, Lijnbaan, но сама улица — транзитная магистраль. | X14: https://www.fundainbusiness.nl/en/winkel/rotterdam/object-89703046-mariniersweg-82-a/ | Y14: =IF($V14=1,N14,"") -> 328.20119 | Z14: =IF($V14=1,P14,"") -> 373.91345 | AA14: =IF($V14=1,IF(AND($D14>=100,$D14<=210),P14,""),"") -> 373.91345 | AB14: =IF($V14=1,IF(AND($D14>=100,$D14<=210),N14,""),"") -> 328.20119
A15: 12 | B15: Witte de Withstraat 55-57, 3012 BM | C15: Винкель + шоурум | D15: 365 | E15: 290 | F15: 75 | G15: 0 | H15: =IF(SUM(E15:G15)=0,"",E15*Методика!$B$5+F15*Методика!$B$6+G15*Методика!$B$7) -> 308.75 | J15: 1876 | K15: Casco | L15: 116250 | M15: не раскрыто | N15: =IFERROR(L15/D15,"") -> 318.49315 | O15: =IFERROR(N15/12,"") -> 26.541096 | P15: =IFERROR(L15/H15,"") -> 376.51822 | Q15: =IFERROR(P15/$P$22-1,"") -> -0.31944332 | R15: 65 | S15: Хуже (дневной трафик) | T15: B1 (культура/хорека) | U15: Свободно (в согласовании) | V15: 1 | W15: ВАЖНО: возможна аренда частями — 145 м² 1-го эт. за €58 000/год (€400/м²) либо 145 + 75 подвал за €65 500/год (€298/м²). Частичный вариант — более близкий по размеру аналог. | X15: https://www.fundainbusiness.nl/en/winkel/rotterdam/object-80869534-witte-de-withstraat-55-57/ | Y15: =IF($V15=1,N15,"") -> 318.49315 | Z15: =IF($V15=1,P15,"") -> 376.51822 | AA15: =IF($V15=1,IF(AND($D15>=100,$D15<=210),P15,""),"") | AB15: =IF($V15=1,IF(AND($D15>=100,$D15<=210),N15,""),"")
A16: 13 | B16: Van Oldenbarneveltstraat 97, 3012 GS | C16: Винкель + шоурум | D16: 109 | E16: 109 | F16: 0 | G16: 0 | H16: =IF(SUM(E16:G16)=0,"",E16*Методика!$B$5+F16*Методика!$B$6+G16*Методика!$B$7) -> 109 | I16: 14.5 | J16: 1987 | K16: Casco | L16: 45600 | M16: 3300 | N16: =IFERROR(L16/D16,"") -> 418.34862 | O16: =IFERROR(N16/12,"") -> 34.862385 | P16: =IFERROR(L16/H16,"") -> 418.34862 | Q16: =IFERROR(P16/$P$22-1,"") -> -0.24383486 | R16: 105 | S16: Сопоставимо / чуть лучше | T16: A2 | U16: Свободно (в согласовании) | V16: 1 | W16: САМЫЙ ЖЁСТКИЙ ТЕСТ ДЛЯ НАС: 109 м² чистого 1-го этажа в ядре (kernwinkelgebied), витрина 14,5 м, за €45 600/год = €418/м². Наш 1-й этаж оценён рынком дороже — см. лист «Сводка». | X16: https://www.fundainbusiness.nl/en/winkel/rotterdam/object-89457010-van-oldenbarneveltstraat-97/ | Y16: =IF($V16=1,N16,"") -> 418.34862 | Z16: =IF($V16=1,P16,"") -> 418.34862 | AA16: =IF($V16=1,IF(AND($D16>=100,$D16<=210),P16,""),"") -> 418.34862 | AB16: =IF($V16=1,IF(AND($D16>=100,$D16<=210),N16,""),"") -> 418.34862
A17: 14 | B17: Oude Binnenweg 117-119, 3012 JC | C17: ХОРЕКА: кафетерий / сэндвич-бар (дневная) | D17: 147 | E17: 129 | F17: 0 | G17: 18 | H17: =IF(SUM(E17:G17)=0,"",E17*Методика!$B$5+F17*Методика!$B$6+G17*Методика!$B$7) -> 135.3 | J17: 1997 | K17: С инвентарём; гудвилл €50 000 | L17: 63504 | M17: не раскрыто | N17: =IFERROR(L17/D17,"") -> 432 | O17: =IFERROR(N17/12,"") -> 36 | P17: =IFERROR(L17/H17,"") -> 469.35698 | Q17: =IFERROR(P17/$P$22-1,"") -> -0.15163725 | R17: 80 | S17: Немного хуже (та же улица, зап. половина) | T17: A2 (та же улица) | U17: Свободно, per direct | V17: 1 | W17: ТА ЖЕ УЛИЦА, БЛИЖАЙШИЙ ПО РАЗМЕРУ (147 м² против 161,1 м²). Прочие уровни = антресоль (vide) 18 м². Терраса 38 м². Гудвилл €50 000 сверх аренды. Лицензия только дневная, алкоголь запрещён, режим 07:00-23:00. | X17: https://www.fundainbusiness.nl/en/horeca/rotterdam/object-43394280-oude-binnenweg-117-119/ | Y17: =IF($V17=1,N17,"") -> 432 | Z17: =IF($V17=1,P17,"") -> 469.35698 | AA17: =IF($V17=1,IF(AND($D17>=100,$D17<=210),P17,""),"") -> 469.35698 | AB17: =IF($V17=1,IF(AND($D17>=100,$D17<=210),N17,""),"") -> 432
A18: 15 | B18: Witte de Withstraat 2, 3012 BP | C18: Винкель | D18: 401 | E18: 215 | F18: 186 | G18: 0 | H18: =IF(SUM(E18:G18)=0,"",E18*Методика!$B$5+F18*Методика!$B$6+G18*Методика!$B$7) -> 261.5 | I18: 36 | J18: 1928 | K18: Тек. состояние: пантри, с/у, потолок с АС, камеры, полы | L18: 125000 | M18: 8020 | N18: =IFERROR(L18/D18,"") -> 311.7207 | O18: =IFERROR(N18/12,"") -> 25.976725 | P18: =IFERROR(L18/H18,"") -> 478.01147 | Q18: =IFERROR(P18/$P$22-1,"") -> -0.13599426 | R18: 70 | S18: Хуже (дневной трафик) | T18: B1 (культура/хорека) | U18: Свободно, per direct | V18: 1 | W18: ВЕРОЯТНЫЙ ДУБЛЬ со строкой Schiedamse Vest 89 — совпадают площадь (401 м²), ставка (€125 000), сервис (€20/м²/год) и год (1928); разбивка 1 эт./подвал зеркально перевёрнута; угловое здание. Разные брокеры: Parc Makelaars vs KroesePaternotte. В выборке учтён ОДИН раз (эта строка). | X18: https://www.fundainbusiness.nl/en/winkel/rotterdam/object-43206580-witte-de-withstraat-2/ | Y18: =IF($V18=1,N18,"") -> 311.7207 | Z18: =IF($V18=1,P18,"") -> 478.01147 | AA18: =IF($V18=1,IF(AND($D18>=100,$D18<=210),P18,""),"") | AB18: =IF($V18=1,IF(AND($D18>=100,$D18<=210),N18,""),"")
A19: 16 | B19: Schiedamse Vest 89, 3012 BG | C19: Винкель + шоурум | D19: 401 | E19: 186 | F19: 215 | G19: 0 | H19: =IF(SUM(E19:G19)=0,"",E19*Методика!$B$5+F19*Методика!$B$6+G19*Методика!$B$7) -> 239.75 | J19: 1928 | K19: Casco, пусто и чисто | L19: 125000 | M19: 8020 | N19: =IFERROR(L19/D19,"") -> 311.7207 | O19: =IFERROR(N19/12,"") -> 25.976725 | P19: =IFERROR(L19/H19,"") -> 521.37643 | Q19: =IFERROR(P19/$P$22-1,"") -> -0.057612096 | R19: 45 | S19: Хуже | T19: B2 | U19: Свободно с 01.01.2026 | V19: 0 | W19: ИСКЛЮЧЁН ИЗ ВЫБОРКИ как вероятный дубль Witte de Withstraat 2 (см. примечание там). Оставлен в таблице для прозрачности. | X19: https://www.fundainbusiness.nl/en/winkel/rotterdam/object-43208908-schiedamse-vest-89/ | Y19: =IF($V19=1,N19,"") | Z19: =IF($V19=1,P19,"") | AA19: =IF($V19=1,IF(AND($D19>=100,$D19<=210),P19,""),"") | AB19: =IF($V19=1,IF(AND($D19>=100,$D19<=210),N19,""),"")
A20: 17 | B20: Karel Doormanstraat 320-322, 3012 GP | C20: Винкель + шоурум | D20: 181 | E20: 181 | F20: 0 | G20: 0 | H20: =IF(SUM(E20:G20)=0,"",E20*Методика!$B$5+F20*Методика!$B$6+G20*Методика!$B$7) -> 181 | J20: 1956 | K20: Casco | L20: 95000 | M20: не раскрыто | N20: =IFERROR(L20/D20,"") -> 524.86188 | O20: =IFERROR(N20/12,"") -> 43.73849 | P20: =IFERROR(L20/H20,"") -> 524.86188 | Q20: =IFERROR(P20/$P$22-1,"") -> -0.051312155 | R20: 85 | S20: Немного хуже | T20: A2 / B1 | U20: Свободно (в согласовании) | V20: 1 | W20: БЛИЗКИЙ АНАЛОГ ПО РАЗМЕРУ (181 м², но весь — 1-й этаж, без подвала). Возможна аренда частями от 85 м² за €47 500/год. Соседи: Omoda, ARO Wonen, Kamera Express, The Cakery. | X20: https://www.fundainbusiness.nl/en/winkel/rotterdam/object-89795637-karel-doormanstraat-320-322/ | Y20: =IF($V20=1,N20,"") -> 524.86188 | Z20: =IF($V20=1,P20,"") -> 524.86188 | AA20: =IF($V20=1,IF(AND($D20>=100,$D20<=210),P20,""),"") -> 524.86188 | AB20: =IF($V20=1,IF(AND($D20>=100,$D20<=210),N20,""),"") -> 524.86188
A21: 18 | B21: Oude Binnenweg 150-A, 3012 JH | C21: ХОРЕКА: снек-бар / кафетерий / мороженое | D21: 140 | E21: 120 | F21: 20 | G21: 0 | H21: =IF(SUM(E21:G21)=0,"",E21*Методика!$B$5+F21*Методика!$B$6+G21*Методика!$B$7) -> 125 | J21: до 1906 | K21: Готово к работе (instapklaar), 3 уровня | L21: 69000 | M21: не раскрыто | N21: =IFERROR(L21/D21,"") -> 492.85714 | O21: =IFERROR(N21/12,"") -> 41.071429 | P21: =IFERROR(L21/H21,"") -> 552 | Q21: =IFERROR(P21/$P$22-1,"") -> -0.00226 | R21: 75 | S21: Немного хуже (та же улица, зап. половина) | T21: A2 (та же улица) | U21: Свободно (в согласовании) | V21: 1 | W21: ТА ЖЕ УЛИЦА. Переуступка инвентаря и гудвилла за €1. Разбивка приблизительна: 140 м² всего, 120 м² торговых. Западная половина Oude Binnenweg (к Eendrachtsplein) тише восточной, где стоим мы. | X21: https://www.fundainbusiness.nl/en/horeca/rotterdam/object-44463783-oude-binnenweg-150-a/ | Y21: =IF($V21=1,N21,"") -> 492.85714 | Z21: =IF($V21=1,P21,"") -> 552 | AA21: =IF($V21=1,IF(AND($D21>=100,$D21<=210),P21,""),"") -> 552 | AB21: =IF($V21=1,IF(AND($D21>=100,$D21<=210),N21,""),"") -> 492.85714
A22: — | B22: Oude Binnenweg 55, 3012 JA | C22: Стрит-ритейл (winkel), 1 эт. + подвал | D22: =Методика!$B$13 -> 161.1 | E22: =Методика!$B$11 -> 115 | F22: =Методика!$B$12 -> 46.1 | G22: 0 | H22: =IF(SUM(E22:G22)=0,"",E22*Методика!$B$5+F22*Методика!$B$6+G22*Методика!$B$7) -> 126.525 | I22: =Методика!$B$14 -> 8 | J22: 1953 | K22: Тек. состояние (данные клиента) | L22: =Методика!$B$10 -> 70000 | M22: не раскрыто | N22: =IFERROR(L22/D22,"") -> 434.51273 | O22: =IFERROR(N22/12,"") -> 36.209394 | P22: =IFERROR(L22/H22,"") -> 553.25035 | R22: 100 | S22: БАЗА СРАВНЕНИЯ | T22: A2 (A-локация, Ooms) | U22: НАШ ОБЪЕКТ | V22: — | W22: Данные клиента: 115 + 46,1 = 161,10 м². Экспозиция Ooms/iLocate по этому же адресу указывает ок. 120 + 42 = 162 м², витрина ок. 8 м, срок 10 + 2×5 лет. Пред. арендатор — Scotch & Soda (сделка 2016, ок. 127 м² + 60 м² подвал). | X22: https://www.ilocate.nl/details/huur-rotterdam-oude-binnenweg-55-3012-ja | Y22: =IF($V22=1,N22,"") | Z22: =IF($V22=1,P22,"") | AA22: =IF($V22=1,IF(AND($D22>=100,$D22<=210),P22,""),"") | AB22: =IF($V22=1,IF(AND($D22>=100,$D22<=210),N22,""),"")
A23: 20 | B23: Karel Doormanstraat 451-A, 3012 GH | C23: Praktijkruimte (меблир., all-in) | D23: 18 | E23: 18 | F23: 0 | G23: 0 | H23: =IF(SUM(E23:G23)=0,"",E23*Методика!$B$5+F23*Методика!$B$6+G23*Методика!$B$7) -> 18 | J23: н/д | K23: Полностью меблировано; вкл. интернет, электр., кухню | L23: 10500 | M23: 0 | N23: =IFERROR(L23/D23,"") -> 583.33333 | O23: =IFERROR(N23/12,"") -> 48.611111 | P23: =IFERROR(L23/H23,"") -> 583.33333 | Q23: =IFERROR(P23/$P$22-1,"") -> 0.054375 | R23: 70 | S23: Хуже | T23: B1 | U23: Свободно | V23: 0 | W23: НЕ СОПОСТАВИМ: сервисный микро-кабинет 18 м² по модели all-in (€875/мес вкл. коммуналку и интернет), возможна аренда по дням. Исключён из выборки. | X23: https://www.fundainbusiness.nl/en/praktijkruimte/rotterdam/object-43330150-karel-doormanstraat-451-a/ | Y23: =IF($V23=1,N23,"") | Z23: =IF($V23=1,P23,"") | AA23: =IF($V23=1,IF(AND($D23>=100,$D23<=210),P23,""),"") | AB23: =IF($V23=1,IF(AND($D23>=100,$D23<=210),N23,""),"")
A24: 21 | B24: Botersloot 52-A, 3011 HJ | C24: Винкель + шоурум | D24: 83 | E24: 37 | F24: 46 | G24: 0 | H24: =IF(SUM(E24:G24)=0,"",E24*Методика!$B$5+F24*Методика!$B$6+G24*Методика!$B$7) -> 48.5 | I24: 5 | J24: 1954 | K24: Тек. состояние / casco | L24: 29700 | M24: не раскрыто | N24: =IFERROR(L24/D24,"") -> 357.83133 | O24: =IFERROR(N24/12,"") -> 29.819277 | P24: =IFERROR(L24/H24,"") -> 612.37113 | Q24: =IFERROR(P24/$P$22-1,"") -> 0.10686082 | R24: 50 | S24: Хуже | T24: B1 | U24: ПОД ОПЦИЕЙ, с 01.09.2026 | V24: 1 | W24: Ближайший аналог по доле подвала (55% площади — подвал, у нас 29%). Stadsdriehoek, «Сохо Роттердама». Под опцией — ставка может не отражать закрытую сделку. | X24: https://www.fundainbusiness.nl/en/winkel/rotterdam/object-80866980-botersloot-52-a/ | Y24: =IF($V24=1,N24,"") -> 357.83133 | Z24: =IF($V24=1,P24,"") -> 612.37113 | AA24: =IF($V24=1,IF(AND($D24>=100,$D24<=210),P24,""),"") | AB24: =IF($V24=1,IF(AND($D24>=100,$D24<=210),N24,""),"")
A25: 22 | B25: Lijnbaan 58, 3012 EP | C25: Винкель + шоурум, 2 уровня | D25: 395 | E25: 200 | F25: 0 | G25: 195 | H25: =IF(SUM(E25:G25)=0,"",E25*Методика!$B$5+F25*Методика!$B$6+G25*Методика!$B$7) -> 268.25 | I25: 8 | J25: 1953 | K25: Не указано | L25: 205000 | M25: 0 | N25: =IFERROR(L25/D25,"") -> 518.98734 | O25: =IFERROR(N25/12,"") -> 43.248945 | P25: =IFERROR(L25/H25,"") -> 764.21249 | Q25: =IFERROR(P25/$P$22-1,"") -> 0.38131407 | R25: 248 | S25: СИЛЬНО ЛУЧШЕ (изм.) | T25: A1 (прайм) | U25: Свободно (в согласовании) | V25: 1 | W25: ОЦЕНКА разбивки: объявление даёт 395 м² на 2 этажах без разбивки; при витрине 8 м принято ~200 м² 1-й эт. + ~195 м² 2-й эт. Прайм-локация: Uniqlo, Nike, Zara, H&M, Primark. Zone-A тариф Lijnbaan (CBRE 2025) — €1 400/м²/год. | X25: https://www.fundainbusiness.nl/en/winkel/rotterdam/object-43305735-lijnbaan-58/ | Y25: =IF($V25=1,N25,"") -> 518.98734 | Z25: =IF($V25=1,P25,"") -> 764.21249 | AA25: =IF($V25=1,IF(AND($D25>=100,$D25<=210),P25,""),"") | AB25: =IF($V25=1,IF(AND($D25>=100,$D25<=210),N25,""),"")
A26: 23 | B26: Meent 96, 3011 JR | C26: Винкель + шоурум | D26: 265 | E26: 195 | F26: 70 | G26: 0 | H26: =IF(SUM(E26:G26)=0,"",E26*Методика!$B$5+F26*Методика!$B$6+G26*Методика!$B$7) -> 212.5 | I26: 9 | J26: 1945-59 | K26: Casco (коммуникации до счётчика, с/у, пантри) | L26: 185000 | M26: 6600 | N26: =IFERROR(L26/D26,"") -> 698.11321 | O26: =IFERROR(N26/12,"") -> 58.176101 | P26: =IFERROR(L26/H26,"") -> 870.58824 | Q26: =IFERROR(P26/$P$22-1,"") -> 0.57358824 | R26: 115 | S26: Лучше (оценка) | T26: A1 (по брокеру) | U26: Свободно, per direct | V26: 1 | W26: Брокер прямо классифицирует как A1. Minervahuis. Соседи: NIKKIE, My Jewellery, Shoe Club, GASSAN. Витрина 9 м — сопоставимо с нашими 8 м. | X26: https://www.fundainbusiness.nl/en/winkel/rotterdam/object-89672108-meent-96/ | Y26: =IF($V26=1,N26,"") -> 698.11321 | Z26: =IF($V26=1,P26,"") -> 870.58824 | AA26: =IF($V26=1,IF(AND($D26>=100,$D26<=210),P26,""),"") | AB26: =IF($V26=1,IF(AND($D26>=100,$D26<=210),N26,""),"")
A27: 24 | B27: Meent 121, 3011 JH | C27: Винкель + шоурум | D27: 160 | E27: 80 | F27: 80 | G27: 0 | H27: =IF(SUM(E27:G27)=0,"",E27*Методика!$B$5+F27*Методика!$B$6+G27*Методика!$B$7) -> 100 | J27: 1950 | K27: Casco | L27: 130000 | M27: 1080 | N27: =IFERROR(L27/D27,"") -> 812.5 | O27: =IFERROR(N27/12,"") -> 67.708333 | P27: =IFERROR(L27/H27,"") -> 1300 | Q27: =IFERROR(P27/$P$22-1,"") -> 1.34975 | R27: 115 | S27: Лучше (оценка) | T27: A1 (по брокеру) | U27: Свободно, per direct | V27: 1 | W27: КЛЮЧЕВОЙ АНАЛОГ ПО РАЗМЕРУ: 160 м² против наших 161,1 м². Timmerhuis (муниципальный памятник). Соседи: Breitling, Aesop, Nespresso. Доля подвала 50% — выше нашей. | X27: https://www.fundainbusiness.nl/en/winkel/rotterdam/object-89465042-meent-121/ | Y27: =IF($V27=1,N27,"") -> 812.5 | Z27: =IF($V27=1,P27,"") -> 1300 | AA27: =IF($V27=1,IF(AND($D27>=100,$D27<=210),P27,""),"") -> 1300 | AB27: =IF($V27=1,IF(AND($D27>=100,$D27<=210),N27,""),"") -> 812.5
A29: ="ИТОГО ПО ВЫБОРКЕ (n = "&SUM($V$4:$V$27)&" из 23; исключены 3)" -> ИТОГО ПО ВЫБОРКЕ (n = 20 из 23; исключены 3) | K29: СРЕДНЕЕ → | L29: =SUMIF($V$4:$V$27,1,L$4:L$27) -> 1935114 | M29: СРЕДНЕЕ → | N29: =AVERAGE(Y$4:Y$27) -> 368.36151 | P29: =AVERAGE(Z$4:Z$27) -> 470.00685 | R29: =AVERAGE(R$4:R$27) -> 96.791667
A30: МЕДИАНА ПО ВЫБОРКЕ | N30: =MEDIAN(Y$4:Y$27) -> 315.10692 | P30: =MEDIAN(Z$4:Z$27) -> 375.21583
A31: НАШ ОБЪЕКТ — ОТКЛОНЕНИЕ ОТ МЕДИАНЫ | N31: =N22/MEDIAN(Y$4:Y$27)-1 -> 0.37893741 | P31: =P22/MEDIAN(Z$4:Z$27)-1 -> 0.4744856

Sheet Проходимость
A1: Проходимость: наш объект против конкурентов
A2: Единственные публично измеренные величины по Роттердаму — Hoogstraat (260 000 чел./нед.) и Lijnbaan (213 000 чел./нед.) по данным RetailSonar, и Oude Binnenweg (86 000 чел./нед.) по данным Ooms. Всё остальное — экспертная оценка по классу локации, функции улицы и удалённости от ядра; такие строки помечены «оценка» и в переговорах как аргумент не используются.
A3: № | B3: Адрес / улица | C3: Проходимость, чел./нед. | D3: Тип данных | E3: Индекс (наш = 100) | F3: Вывод против нашего объекта | G3: Класс локации | H3: €/м²/год (привед.) | I3: Обоснование оценки проходимости
A4: 1 | B4: Korte Hoogstraat 9-A, 3011 GJ | C4: =Методика!$B$21 -> 260000 | D4: ИЗМЕРЕНО | E4: 300 | F4: СИЛЬНО ЛУЧШЕ (изм.) | G4: A1 (прайм) | H4: =IFERROR(Все_объекты!P9,"") -> 302.38727 | I4: ИЗМЕРЕНО по Hoogstraat: 260 000 чел./нед. (RetailSonar, 3-е место в НЛ). Korte Hoogstraat — отрезок у входа в Koopgoot, т.е. не ниже среднего по Hoogstraat.
A5: 2 | B5: Korte Hoogstraat 19, 3011 GK | C5: =Методика!$B$21 -> 260000 | D5: ИЗМЕРЕНО | E5: 300 | F5: СИЛЬНО ЛУЧШЕ (изм.) | G5: A1 (прайм) | H5: =IFERROR(Все_объекты!P13,"") -> 359.19732 | I5: То же, что и Korte Hoogstraat 9-A: измеренный поток Hoogstraat 260 000 чел./нед.
A6: 3 | B6: Lijnbaan 58, 3012 EP | C6: =Методика!$B$20 -> 213000 | D6: ИЗМЕРЕНО | E6: 248 | F6: СИЛЬНО ЛУЧШЕ (изм.) | G6: A1 (прайм) | H6: =IFERROR(Все_объекты!P25,"") -> 764.21249 | I6: ИЗМЕРЕНО: 213 000 чел./нед. (RetailSonar, 7-е место в НЛ). Ядро kernwinkelgebied: Uniqlo, Nike, Zara, H&M, Primark.
A7: 4 | B7: Meent 96, 3011 JR | C7: нет публичного замера | D7: ОЦЕНКА | E7: 115 | F7: Лучше (оценка) | G7: A1 (по брокеру) | H7: =IFERROR(Все_объекты!P26,"") -> 870.58824 | I7: Оценка. Брокер прямо указывает «A1 premium town centre location». Соседи: NIKKIE, My Jewellery, GASSAN.
A8: 5 | B8: Meent 121, 3011 JH | C8: нет публичного замера | D8: ОЦЕНКА | E8: 115 | F8: Лучше (оценка) | G8: A1 (по брокеру) | H8: =IFERROR(Все_объекты!P27,"") -> 1300 | I8: Оценка. Брокер классифицирует Meent как A1. Качественная, но малоформатная улица: премиальные бренды (Breitling, Aesop, Nespresso), поток ниже Lijnbaan при более высоком чеке.
A9: 6 | B9: Schouwburgplein 9, 3012 CL | C9: нет публичного замера | D9: ОЦЕНКА | E9: 105 | F9: Сопоставимо / чуть лучше | G9: A2 | H9: =IFERROR(Все_объекты!P5,"") -> 210 | I9: Оценка. 500 м до Centraal Station, транзит между вокзалом и Lijnbaan высокий, но это площадь событийно-досугового назначения: поток мимо есть, витринной задержки мало.
A10: 7 | B10: Van Oldenbarneveltstraat 97, 3012 GS | C10: нет публичного замера | D10: ОЦЕНКА | E10: 105 | F10: Сопоставимо / чуть лучше | G10: A2 | H10: =IFERROR(Все_объекты!P16,"") -> 418.34862 | I10: Оценка. Параллель Lijnbaan внутри ядра, бутиковый профиль. Поток сопоставим с нашим или чуть выше.
A11: — | B11: Oude Binnenweg 55, 3012 JA | C11: =Методика!$B$19 -> 86000 | D11: ИЗМЕРЕНО | E11: 100 | F11: БАЗА СРАВНЕНИЯ (100) | G11: A2 (A-локация, Ooms) | H11: =IFERROR(Все_объекты!P22,"") -> 553.25035 | I11: Измерено: Ooms Makelaars, ок. 86 000 чел./нед., A-локация. Восточная (более оживлённая) половина улицы.
A12: 9 | B12: Karel Doormanstraat 320-322, 3012 GP | C12: нет публичного замера | D12: ОЦЕНКА | E12: 85 | F12: Немного хуже | G12: A2 / B1 | H12: =IFERROR(Все_объекты!P20,"") -> 524.86188 | I12: Оценка. Пересекает Oude Binnenweg; отрезок ближе к ядру. Соседи: Omoda, Kamera Express, The Cakery.
A13: 10 | B13: Karel Doormanstraat 257-259, 3012 GH | C13: нет публичного замера | D13: ОЦЕНКА | E13: 80 | F13: Немного хуже | G13: A2 / B1 | H13: =IFERROR(Все_объекты!P10,"") -> 305.49898 | I13: Оценка. Тот же коридор, отрезок дальше от ядра, ближе к Schouwburgplein.
A14: 11 | B14: Oude Binnenweg 117-119, 3012 JC | C14: нет публичного замера | D14: ОЦЕНКА | E14: 80 | F14: Немного хуже (та же улица, зап. половина) | G14: A2 (та же улица) | H14: =IFERROR(Все_объекты!P17,"") -> 469.35698 | I14: Оценка. Та же улица, западная половина; чуть ближе к ядру, чем 150-A, но дальше нас.
A15: 12 | B15: Oude Binnenweg 150-A, 3012 JH | C15: нет публичного замера | D15: ОЦЕНКА | E15: 75 | F15: Немного хуже (та же улица, зап. половина) | G15: A2 (та же улица) | H15: =IFERROR(Все_объекты!P21,"") -> 552 | I15: Оценка. ТА ЖЕ УЛИЦА (86 000 чел./нед. в среднем), но западная половина у Eendrachtsplein — тише восточной. Мы стоим в восточной половине, у Binnenwegplein (соседи по экспозиции: ANWB 44-46, My Jewellery 57A, далее TK Maxx, MediaMarkt, Uniqlo).
A16: 13 | B16: Witte de Withstraat 2, 3012 BP | C16: нет публичного замера | D16: ОЦЕНКА | E16: 70 | F16: Хуже (дневной трафик) | G16: B1 (культура/хорека) | H16: =IFERROR(Все_объекты!P18,"") -> 478.01147 | I16: Оценка. Улица культуры и ночной жизни: галереи, бары, рестораны. Пик — вечер и выходные; дневной торговый трафик заметно ниже нашего.
A17: 14 | B17: Karel Doormanstraat 451-A, 3012 GH | C17: нет публичного замера | D17: ОЦЕНКА | E17: 70 | F17: Хуже | G17: B1 | H17: =IFERROR(Все_объекты!P23,"") -> 583.33333 | I17: Оценка. Северный отрезок улицы, вне торгового ядра.
A18: 15 | B18: Witte de Withstraat 55-57, 3012 BM | C18: нет публичного замера | D18: ОЦЕНКА | E18: 65 | F18: Хуже (дневной трафик) | G18: B1 (культура/хорека) | H18: =IFERROR(Все_объекты!P15,"") -> 376.51822 | I18: Оценка. То же, отрезок дальше от Coolsingel.
A19: 16 | B19: Mariniersweg 82-A, 3011 NT | C19: нет публичного замера | D19: ОЦЕНКА | E19: 60 | F19: Хуже | G19: B1 | H19: =IFERROR(Все_объекты!P14,"") -> 373.91345 | I19: Оценка. Рядом Meent и Hoogstraat, но сама Mariniersweg — транзитная магистраль, а не витринная улица.
A20: 17 | B20: Botersloot 52-A, 3011 HJ | C20: нет публичного замера | D20: ОЦЕНКА | E20: 50 | F20: Хуже | G20: B1 | H20: =IFERROR(Все_объекты!P24,"") -> 612.37113 | I20: Оценка. Stadsdriehoek, нишевый «Сохо Роттердама»: независимые бутики и рестораны, целевой, а не проходной поток.
A21: 18 | B21: Groenendaal 245, 3011 ZW | C21: нет публичного замера | D21: ОЦЕНКА | E21: 45 | F21: Хуже | G21: B1 | H21: =IFERROR(Все_объекты!P6,"") -> 224.35897 | I21: Оценка. У Oostplein/Blaak, первый этаж жилого комплекса; поток обеспечен местными жителями (Albert Heijn, Trekpleister), а не шопинг-туризмом.
A22: 19 | B22: Goudsesingel 247, 3031 EL | C22: нет публичного замера | D22: ОЦЕНКА | E22: 45 | F22: Хуже | G22: B1 | H22: =IFERROR(Все_объекты!P7,"") -> 275.22936 | I22: Оценка. Laurenskwartier, широкая автомобильная артерия, пешеходный поток низкий.
A23: 20 | B23: Goudsesingel 227-229, 3031 EK | C23: нет публичного замера | D23: ОЦЕНКА | E23: 45 | F23: Хуже | G23: B1 | H23: =IFERROR(Все_объекты!P12,"") -> 352.21239 | I23: Оценка. То же.
A24: 21 | B24: Schiedamse Vest 89, 3012 BG | C24: нет публичного замера | D24: ОЦЕНКА | E24: 45 | F24: Хуже | G24: B2 | H24: =IFERROR(Все_объекты!P19,"") -> 521.37643 | I24: Оценка. Транспортная артерия на краю ядра.
A25: 22 | B25: Schiedamsedijk 3, 3011 EB | C25: нет публичного замера | D25: ОЦЕНКА | E25: 40 | F25: Хуже | G25: B2 | H25: =IFERROR(Все_объекты!P4,"") | I25: Оценка. То же.
A26: 23 | B26: Westblaak 159, 3012 KJ | C26: нет публичного замера | D26: ОЦЕНКА | E26: 40 | F26: Хуже | G26: B2 | H26: =IFERROR(Все_объекты!P8,"") -> 279.85075 | I26: Оценка. Westblaak — магистраль с интенсивным автомобильным, но не пешеходным потоком.
A27: 24 | B27: Schiedamsedijk 8-A, 3011 EC | C27: нет публичного замера | D27: ОЦЕНКА | E27: 40 | F27: Хуже | G27: B2 | H27: =IFERROR(Все_объекты!P11,"") -> 351.21951 | I27: Оценка. Южнее Churchillplein, вторичная локация; нижний уровень — вообще склад/гараж.
A29: ВЫВОД ПО ПРОХОДИМОСТИ
A30: • Лучше нас — 5 объектов из 22: Lijnbaan 58 и оба лота на Korte Hoogstraat (измеренный поток в 2,5–3 раза выше нашего), плюс Meent 96 и Meent 121 (оценочно на 15% выше). Все пять — ядро kernwinkelgebied.
A31: • Сопоставимо с нами — 2 объекта: Schouwburgplein 9 и Van Oldenbarneveltstraat 97 (оценочно +5%).
A32: • Хуже нас — 15 объектов, то есть две трети выборки. Из них 11 — заметно хуже (индекс 40–60): Westblaak, Goudsesingel, Schiedamsedijk, Schiedamse Vest, Groenendaal, Botersloot, Witte de Withstraat.
A33: • Отдельно: два объекта на НАШЕЙ улице (Oude Binnenweg 150-A и 117-119) стоят в её западной, более тихой половине. Наша позиция на улице лучше, чем у них.
A34: • Практический смысл: по проходимости мы находимся в верхней трети выборки, но заметно ниже прайма. Из 22 конкурентов только 5 объективно лучше нас по потоку — и все пять просят за приведённый метр больше нашего, кроме двух крупноформатных лотов на Korte Hoogstraat, где ставку вниз тянет эффект масштаба (834 и 465 м²), а не слабость локации.
